Workbook

Sheet Instrucciones
A1: Polla Mundial 2026 — Formato manual en Excel
A3: Como usar este archivo:
A4: 1. Hoja "Grupos": una persona (el participante) llena las columnas "Pron. Local" y "Pron. Visitante" con su pronostico de marcador para cada uno de los 72 partidos. Otra persona (el administrador) llena "Real Local" y "Real Visitante" a medida que se juegan los partidos reales.
A5: 2. Hoja "Tabla Grupos": se calcula sola (no se toca) — arma la tabla de posiciones de cada grupo, tanto real como segun el pronostico, y compara quien clasifico a Dieciseisavos (32 equipos).
A6: 3. Hoja "Bracket": para cada llave (32avos a Final), el participante escribe manualmente que 2 equipos cree que se enfrentan y quien gana; el administrador llena los equipos y el ganador real. Los puntos de equipo clasificado y de llave acertada se calculan solos.
A7: 4. Hoja "Goleador": el participante escribe 1 nombre; el administrador escribe hasta 3 nombres reales (estos son los "maximos goleadores" oficiales del torneo).
A8: 5. Hoja "Resumen Puntaje": muestra el total, fase por fase, calculado automaticamente. No se toca.
A10: IMPORTANTE — simplificaciones de esta version (frente al motor real de la app):
A11: - El desempate de la tabla de grupos usa Puntos -> Diferencia de gol -> Goles a favor. NO incluye el mini-cuadrangular de enfrentamientos directos (head-to-head) que usa la FIFA cuando 2+ equipos quedan exactamente empatados en esos 3 criterios. En ese caso, el desempate aqui es arbitrario (por el orden en que aparecen los equipos).
A12: - El bracket NO se arma solo a partir de tus pronosticos de grupo: cada ronda se llena a mano, incluyendo que equipos crees que se enfrentan.
A13: - Las llaves se comparan por posicion (la llave #5 real contra la llave #5 pronosticada), no por "si esa pareja de equipos ocurrio en cualquier posicion de la ronda" como hace la app.
A14: - El nombre del goleador se compara sin distinguir mayusculas/minusculas ni espacios extra, pero SI debe ser el mismo nombre (ej: "Mbappe" y "Kylian Mbappe" cuentan distinto salvo que escribas exactamente igual en ambos lados).
... A21: Goleador: 10 pts (todo o nada)

Sheet Equipos
A1: Grupo | B1: Equipo
A2: A | B2: México
A3: A | B3: Sudáfrica
A4: A | B4: Corea del Sur
A5: A | B5: República Checa
A6: B | B6: Canadá
A7: B | B7: Bosnia y Herzegovina
A8: B | B8: Catar
A9: B | B9: Suiza
A10: C | B10: Brasil
A11: C | B11: Marruecos
A12: C | B12: Haití
... A49: L | B49: Panamá

Sheet Grupos
A1: # | B1: Grupo | C1: Local | D1: Visitante | E1: Pron. Local | F1: Pron. Visitante | G1: Real Local | H1: Real Visitante | I1: Puntos
A2: 1 | B2: A | C2: México | D2: Sudáfrica | I2: =IF(OR(G2="",H2="",E2="",F2=""),0,IF(AND(E2=G2,F2=H2),3,IF(SIGN(E2-F2)=SIGN(G2-H2),1,0)))
A3: 2 | B3: A | C3: Corea del Sur | D3: República Checa | I3: =IF(OR(G3="",H3="",E3="",F3=""),0,IF(AND(E3=G3,F3=H3),3,IF(SIGN(E3-F3)=SIGN(G3-H3),1,0)))
A4: 3 | B4: A | C4: República Checa | D4: Sudáfrica | I4: =IF(OR(G4="",H4="",E4="",F4=""),0,IF(AND(E4=G4,F4=H4),3,IF(SIGN(E4-F4)=SIGN(G4-H4),1,0)))
A5: 4 | B5: A | C5: México | D5: Corea del Sur | I5: =IF(OR(G5="",H5="",E5="",F5=""),0,IF(AND(E5=G5,F5=H5),3,IF(SIGN(E5-F5)=SIGN(G5-H5),1,0)))
A6: 5 | B6: A | C6: República Checa | D6: México | I6: =IF(OR(G6="",H6="",E6="",F6=""),0,IF(AND(E6=G6,F6=H6),3,IF(SIGN(E6-F6)=SIGN(G6-H6),1,0)))
A7: 6 | B7: A | C7: Sudáfrica | D7: Corea del Sur | I7: =IF(OR(G7="",H7="",E7="",F7=""),0,IF(AND(E7=G7,F7=H7),3,IF(SIGN(E7-F7)=SIGN(G7-H7),1,0)))
A8: 7 | B8: B | C8: Canadá | D8: Bosnia y Herzegovina | I8: =IF(OR(G8="",H8="",E8="",F8=""),0,IF(AND(E8=G8,F8=H8),3,IF(SIGN(E8-F8)=SIGN(G8-H8),1,0)))
A9: 8 | B9: B | C9: Catar | D9: Suiza | I9: =IF(OR(G9="",H9="",E9="",F9=""),0,IF(AND(E9=G9,F9=H9),3,IF(SIGN(E9-F9)=SIGN(G9-H9),1,0)))
A10: 9 | B10: B | C10: Suiza | D10: Bosnia y Herzegovina | I10: =IF(OR(G10="",H10="",E10="",F10=""),0,IF(AND(E10=G10,F10=H10),3,IF(SIGN(E10-F10)=SIGN(G10-H10),1,0)))
A11: 10 | B11: B | C11: Canadá | D11: Catar | I11: =IF(OR(G11="",H11="",E11="",F11=""),0,IF(AND(E11=G11,F11=H11),3,IF(SIGN(E11-F11)=SIGN(G11-H11),1,0)))
A12: 11 | B12: B | C12: Suiza | D12: Canadá | I12: =IF(OR(G12="",H12="",E12="",F12=""),0,IF(AND(E12=G12,F12=H12),3,IF(SIGN(E12-F12)=SIGN(G12-H12),1,0)))
A13: 12 | B13: B | C13: Bosnia y Herzegovina | D13: Catar | I13: =IF(OR(G13="",H13="",E13="",F13=""),0,IF(AND(E13=G13,F13=H13),3,IF(SIGN(E13-F13)=SIGN(G13-H13),1,0)))
... A73: 72 | B73: L | C73: Croacia | D73: Ghana | I73: =IF(OR(G73="",H73="",E73="",F73=""),0,IF(AND(E73=G73,F73=H73),3,IF(SIGN(E73-F73)=SIGN(G73-H73),1,0)))
H74: TOTAL GRUPOS | I74: =SUM(I2:I73)

Sheet Tabla Grupos
B1: Equipo | C1: J | D1: G | E1: E | F1: P | G1: GF | H1: GC | I1: DG | J1: Pts | K1: OrdenReal | L1: PosReal | M1: J | N1: G | O1: E | P1: P | Q1: GF | R1: GC | S1: DG | T1: Pts | U1: OrdenPron | V1: PosPron | W1: Posicion | X1: EquipoReal(pos) | Y1: EquipoPron(pos) | Z1: PtsPosicion | AA1: PtsReal(pos) | AB1: DGReal(pos) | AC1: GFReal(pos) | AD1: PtsPron(pos) | AE1: DGPron(pos) | AF1: GFPron(pos)
A2: A | B2: México | C2: =SUMPRODUCT((Grupos!$B$2:$B$73=$A2)*((Grupos!$C$2:$C$73=$B2)+(Grupos!$D$2:$D$73=$B2))*(Grupos!$G$2:$G$73<>"")) | D2: =SUMPRODUCT((Grupos!$B$2:$B$73=$A2)*(Grupos!$C$2:$C$73=$B2)*(Grupos!$G$2:$G$73>Grupos!$H$2:$H$73))+SUMPRODUCT((Grupos!$B$2:$B$73=$A2)*(Grupos!$D$2:$D$73=$B2)*(Grupos!$H$2:$H$73>Grupos!$G$2:$G$73)) | E2: =SUMPRODUCT((Grupos!$B$2:$B$73=$A2)*((Grupos!$C$2:$C$73=$B2)+(Grupos!$D$2:$D$73=$B2))*(Grupos!$G$2:$G$73=Grupos!$H$2:$H$73)*(Grupos!$G$2:$G$73<>"")) | F2: =C2-D2-E2 | G2: =SUMPRODUCT((Grupos!$B$2:$B$73=$A2)*(Grupos!$C$2:$C$73=$B2)*Grupos!$G$2:$G$73)+SUMPRODUCT((Grupos!$B$2:$B$73=$A2)*(Grupos!$D$2:$D$73=$B2)*Grupos!$H$2:$H$73) | H2: =SUMPRODUCT((Grupos!$B$2:$B$73=$A2)*(Grupos!$C$2:$C$73=$B2)*Grupos!$H$2:$H$73)+SUMPRODUCT((Grupos!$B$2:$B$73=$A2)*(Grupos!$D$2:$D$73=$B2)*Grupos!$G$2:$G$73) | I2: =G2-H2 | J2: =D2*3+E2 | K2: =J2*1000000+I2*1000+G2*10-0 | L2: =1+COUNTIF($K$2:$K$5,">"&K2) | M2: =SUMPRODUCT((Grupos!$B$2:$B$73=$A2)*((Grupos!$C$2:$C$73=$B2)+(Grupos!$D$2:$D$73=$B2))*(Grupos!$E$2:$E$73<>"")) | N2: =SUMPRODUCT((Grupos!$B$2:$B$73=$A2)*(Grupos!$C$2:$C$73=$B2)*(Grupos!$E$2:$E$73>Grupos!$F$2:$F$73))+SUMPRODUCT((Grupos!$B$2:$B$73=$A2)*(Grupos!$D$2:$D$73=$B2)*(Grupos!$F$2:$F$73>Grupos!$E$2:$E$73)) | O2: =SUMPRODUCT((Grupos!$B$2:$B$73=$A2)*((Grupos!$C$2:$C$73=$B2)+(Grupos!$D$2:$D$73=$B2))*(Grupos!$E$2:$E$73=Grupos!$F$2:$F$73)*(Grupos!$E$2:$E$73<>"")) | P2: =M2-N2-O2 | Q2: =SUMPRODUCT((Grupos!$B$2:$B$73=$A2)*(Grupos!$C$2:$C$73=$B2)*Grupos!$E$2:$E$73)+SUMPRODUCT((Grupos!$B$2:$B$73=$A2)*(Grupos!$D$2:$D$73=$B2)*Grupos!$F$2:$F$73) | R2: =SUMPRODUCT((Grupos!$B$2:$B$73=$A2)*(Grupos!$C$2:$C$73=$B2)*Grupos!$F$2:$F$73)+SUMPRODUCT((Grupos!$B$2:$B$73=$A2)*(Grupos!$D$2:$D$73=$B2)*Grupos!$E$2:$E$73) | S2: =Q2-R2 | T2: =N2*3+O2 | U2: =T2*1000000+S2*1000+Q2*10-0 | V2: =1+COUNTIF($U$2:$U$5,">"&U2) | W2: 1 | X2: =INDEX($B$2:$B$5,MATCH(W2,$L$2:$L$5,0)) | Y2: =INDEX($B$2:$B$5,MATCH(W2,$V$2:$V$5,0)) | Z2: =IF(AND(X2<>"",X2=Y2),1,0) | AA2: =INDEX($J$2:$J$5,MATCH(W2,$L$2:$L$5,0)) | AB2: =INDEX($I$2:$I$5,MATCH(W2,$L$2:$L$5,0)) | AC2: =INDEX($G$2:$G$5,MATCH(W2,$L$2:$L$5,0)) | AD2: =INDEX($T$2:$T$5,MATCH(W2,$V$2:$V$5,0)) | AE2: =INDEX($S$2:$S$5,MATCH(W2,$V$2:$V$5,0)) | AF2: =INDEX($Q$2:$Q$5,MATCH(W2,$V$2:$V$5,0))
A3: A | B3: Sudáfrica | C3: =SUMPRODUCT((Grupos!$B$2:$B$73=$A3)*((Grupos!$C$2:$C$73=$B3)+(Grupos!$D$2:$D$73=$B3))*(Grupos!$G$2:$G$73<>"")) | D3: =SUMPRODUCT((Grupos!$B$2:$B$73=$A3)*(Grupos!$C$2:$C$73=$B3)*(Grupos!$G$2:$G$73>Grupos!$H$2:$H$73))+SUMPRODUCT((Grupos!$B$2:$B$73=$A3)*(Grupos!$D$2:$D$73=$B3)*(Grupos!$H$2:$H$73>Grupos!$G$2:$G$73)) | E3: =SUMPRODUCT((Grupos!$B$2:$B$73=$A3)*((Grupos!$C$2:$C$73=$B3)+(Grupos!$D$2:$D$73=$B3))*(Grupos!$G$2:$G$73=Grupos!$H$2:$H$73)*(Grupos!$G$2:$G$73<>"")) | F3: =C3-D3-E3 | G3: =SUMPRODUCT((Grupos!$B$2:$B$73=$A3)*(Grupos!$C$2:$C$73=$B3)*Grupos!$G$2:$G$73)+SUMPRODUCT((Grupos!$B$2:$B$73=$A3)*(Grupos!$D$2:$D$73=$B3)*Grupos!$H$2:$H$73) | H3: =SUMPRODUCT((Grupos!$B$2:$B$73=$A3)*(Grupos!$C$2:$C$73=$B3)*Grupos!$H$2:$H$73)+SUMPRODUCT((Grupos!$B$2:$B$73=$A3)*(Grupos!$D$2:$D$73=$B3)*Grupos!$G$2:$G$73) | I3: =G3-H3 | J3: =D3*3+E3 | K3: =J3*1000000+I3*1000+G3*10-1 | L3: =1+COUNTIF($K$2:$K$5,">"&K3) | M3: =SUMPRODUCT((Grupos!$B$2:$B$73=$A3)*((Grupos!$C$2:$C$73=$B3)+(Grupos!$D$2:$D$73=$B3))*(Grupos!$E$2:$E$73<>"")) | N3: =SUMPRODUCT((Grupos!$B$2:$B$73=$A3)*(Grupos!$C$2:$C$73=$B3)*(Grupos!$E$2:$E$73>Grupos!$F$2:$F$73))+SUMPRODUCT((Grupos!$B$2:$B$73=$A3)*(Grupos!$D$2:$D$73=$B3)*(Grupos!$F$2:$F$73>Grupos!$E$2:$E$73)) | O3: =SUMPRODUCT((Grupos!$B$2:$B$73=$A3)*((Grupos!$C$2:$C$73=$B3)+(Grupos!$D$2:$D$73=$B3))*(Grupos!$E$2:$E$73=Grupos!$F$2:$F$73)*(Grupos!$E$2:$E$73<>"")) | P3: =M3-N3-O3 | Q3: =SUMPRODUCT((Grupos!$B$2:$B$73=$A3)*(Grupos!$C$2:$C$73=$B3)*Grupos!$E$2:$E$73)+SUMPRODUCT((Grupos!$B$2:$B$73=$A3)*(Grupos!$D$2:$D$73=$B3)*Grupos!$F$2:$F$73) | R3: =SUMPRODUCT((Grupos!$B$2:$B$73=$A3)*(Grupos!$C$2:$C$73=$B3)*Grupos!$F$2:$F$73)+SUMPRODUCT((Grupos!$B$2:$B$73=$A3)*(Grupos!$D$2:$D$73=$B3)*Grupos!$E$2:$E$73) | S3: =Q3-R3 | T3: =N3*3+O3 | U3: =T3*1000000+S3*1000+Q3*10-1 | V3: =1+COUNTIF($U$2:$U$5,">"&U3) | W3: 2 | X3: =INDEX($B$2:$B$5,MATCH(W3,$L$2:$L$5,0)) | Y3: =INDEX($B$2:$B$5,MATCH(W3,$V$2:$V$5,0)) | Z3: =IF(AND(X3<>"",X3=Y3),1,0) | AA3: =INDEX($J$2:$J$5,MATCH(W3,$L$2:$L$5,0)) | AB3: =INDEX($I$2:$I$5,MATCH(W3,$L$2:$L$5,0)) | AC3: =INDEX($G$2:$G$5,MATCH(W3,$L$2:$L$5,0)) | AD3: =INDEX($T$2:$T$5,MATCH(W3,$V$2:$V$5,0)) | AE3: =INDEX($S$2:$S$5,MATCH(W3,$V$2:$V$5,0)) | AF3: =INDEX($Q$2:$Q$5,MATCH(W3,$V$2:$V$5,0))
A4: A | B4: Corea del Sur | C4: =SUMPRODUCT((Grupos!$B$2:$B$73=$A4)*((Grupos!$C$2:$C$73=$B4)+(Grupos!$D$2:$D$73=$B4))*(Grupos!$G$2:$G$73<>"")) | D4: =SUMPRODUCT((Grupos!$B$2:$B$73=$A4)*(Grupos!$C$2:$C$73=$B4)*(Grupos!$G$2:$G$73>Grupos!$H$2:$H$73))+SUMPRODUCT((Grupos!$B$2:$B$73=$A4)*(Grupos!$D$2:$D$73=$B4)*(Grupos!$H$2:$H$73>Grupos!$G$2:$G$73)) | E4: =SUMPRODUCT((Grupos!$B$2:$B$73=$A4)*((Grupos!$C$2:$C$73=$B4)+(Grupos!$D$2:$D$73=$B4))*(Grupos!$G$2:$G$73=Grupos!$H$2:$H$73)*(Grupos!$G$2:$G$73<>"")) | F4: =C4-D4-E4 | G4: =SUMPRODUCT((Grupos!$B$2:$B$73=$A4)*(Grupos!$C$2:$C$73=$B4)*Grupos!$G$2:$G$73)+SUMPRODUCT((Grupos!$B$2:$B$73=$A4)*(Grupos!$D$2:$D$73=$B4)*Grupos!$H$2:$H$73) | H4: =SUMPRODUCT((Grupos!$B$2:$B$73=$A4)*(Grupos!$C$2:$C$73=$B4)*Grupos!$H$2:$H$73)+SUMPRODUCT((Grupos!$B$2:$B$73=$A4)*(Grupos!$D$2:$D$73=$B4)*Grupos!$G$2:$G$73) | I4: =G4-H4 | J4: =D4*3+E4 | K4: =J4*1000000+I4*1000+G4*10-2 | L4: =1+COUNTIF($K$2:$K$5,">"&K4) | M4: =SUMPRODUCT((Grupos!$B$2:$B$73=$A4)*((Grupos!$C$2:$C$73=$B4)+(Grupos!$D$2:$D$73=$B4))*(Grupos!$E$2:$E$73<>"")) | N4: =SUMPRODUCT((Grupos!$B$2:$B$73=$A4)*(Grupos!$C$2:$C$73=$B4)*(Grupos!$E$2:$E$73>Grupos!$F$2:$F$73))+SUMPRODUCT((Grupos!$B$2:$B$73=$A4)*(Grupos!$D$2:$D$73=$B4)*(Grupos!$F$2:$F$73>Grupos!$E$2:$E$73)) | O4: =SUMPRODUCT((Grupos!$B$2:$B$73=$A4)*((Grupos!$C$2:$C$73=$B4)+(Grupos!$D$2:$D$73=$B4))*(Grupos!$E$2:$E$73=Grupos!$F$2:$F$73)*(Grupos!$E$2:$E$73<>"")) | P4: =M4-N4-O4 | Q4: =SUMPRODUCT((Grupos!$B$2:$B$73=$A4)*(Grupos!$C$2:$C$73=$B4)*Grupos!$E$2:$E$73)+SUMPRODUCT((Grupos!$B$2:$B$73=$A4)*(Grupos!$D$2:$D$73=$B4)*Grupos!$F$2:$F$73) | R4: =SUMPRODUCT((Grupos!$B$2:$B$73=$A4)*(Grupos!$C$2:$C$73=$B4)*Grupos!$F$2:$F$73)+SUMPRODUCT((Grupos!$B$2:$B$73=$A4)*(Grupos!$D$2:$D$73=$B4)*Grupos!$E$2:$E$73) | S4: =Q4-R4 | T4: =N4*3+O4 | U4: =T4*1000000+S4*1000+Q4*10-2 | V4: =1+COUNTIF($U$2:$U$5,">"&U4) | W4: 3 | X4: =INDEX($B$2:$B$5,MATCH(W4,$L$2:$L$5,0)) | Y4: =INDEX($B$2:$B$5,MATCH(W4,$V$2:$V$5,0)) | Z4: =IF(AND(X4<>"",X4=Y4),1,0) | AA4: =INDEX($J$2:$J$5,MATCH(W4,$L$2:$L$5,0)) | AB4: =INDEX($I$2:$I$5,MATCH(W4,$L$2:$L$5,0)) | AC4: =INDEX($G$2:$G$5,MATCH(W4,$L$2:$L$5,0)) | AD4: =INDEX($T$2:$T$5,MATCH(W4,$V$2:$V$5,0)) | AE4: =INDEX($S$2:$S$5,MATCH(W4,$V$2:$V$5,0)) | AF4: =INDEX($Q$2:$Q$5,MATCH(W4,$V$2:$V$5,0))
A5: A | B5: República Checa | C5: =SUMPRODUCT((Grupos!$B$2:$B$73=$A5)*((Grupos!$C$2:$C$73=$B5)+(Grupos!$D$2:$D$73=$B5))*(Grupos!$G$2:$G$73<>"")) | D5: =SUMPRODUCT((Grupos!$B$2:$B$73=$A5)*(Grupos!$C$2:$C$73=$B5)*(Grupos!$G$2:$G$73>Grupos!$H$2:$H$73))+SUMPRODUCT((Grupos!$B$2:$B$73=$A5)*(Grupos!$D$2:$D$73=$B5)*(Grupos!$H$2:$H$73>Grupos!$G$2:$G$73)) | E5: =SUMPRODUCT((Grupos!$B$2:$B$73=$A5)*((Grupos!$C$2:$C$73=$B5)+(Grupos!$D$2:$D$73=$B5))*(Grupos!$G$2:$G$73=Grupos!$H$2:$H$73)*(Grupos!$G$2:$G$73<>"")) | F5: =C5-D5-E5 | G5: =SUMPRODUCT((Grupos!$B$2:$B$73=$A5)*(Grupos!$C$2:$C$73=$B5)*Grupos!$G$2:$G$73)+SUMPRODUCT((Grupos!$B$2:$B$73=$A5)*(Grupos!$D$2:$D$73=$B5)*Grupos!$H$2:$H$73) | H5: =SUMPRODUCT((Grupos!$B$2:$B$73=$A5)*(Grupos!$C$2:$C$73=$B5)*Grupos!$H$2:$H$73)+SUMPRODUCT((Grupos!$B$2:$B$73=$A5)*(Grupos!$D$2:$D$73=$B5)*Grupos!$G$2:$G$73) | I5: =G5-H5 | J5: =D5*3+E5 | K5: =J5*1000000+I5*1000+G5*10-3 | L5: =1+COUNTIF($K$2:$K$5,">"&K5) | M5: =SUMPRODUCT((Grupos!$B$2:$B$73=$A5)*((Grupos!$C$2:$C$73=$B5)+(Grupos!$D$2:$D$73=$B5))*(Grupos!$E$2:$E$73<>"")) | N5: =SUMPRODUCT((Grupos!$B$2:$B$73=$A5)*(Grupos!$C$2:$C$73=$B5)*(Grupos!$E$2:$E$73>Grupos!$F$2:$F$73))+SUMPRODUCT((Grupos!$B$2:$B$73=$A5)*(Grupos!$D$2:$D$73=$B5)*(Grupos!$F$2:$F$73>Grupos!$E$2:$E$73)) | O5: =SUMPRODUCT((Grupos!$B$2:$B$73=$A5)*((Grupos!$C$2:$C$73=$B5)+(Grupos!$D$2:$D$73=$B5))*(Grupos!$E$2:$E$73=Grupos!$F$2:$F$73)*(Grupos!$E$2:$E$73<>"")) | P5: =M5-N5-O5 | Q5: =SUMPRODUCT((Grupos!$B$2:$B$73=$A5)*(Grupos!$C$2:$C$73=$B5)*Grupos!$E$2:$E$73)+SUMPRODUCT((Grupos!$B$2:$B$73=$A5)*(Grupos!$D$2:$D$73=$B5)*Grupos!$F$2:$F$73) | R5: =SUMPRODUCT((Grupos!$B$2:$B$73=$A5)*(Grupos!$C$2:$C$73=$B5)*Grupos!$F$2:$F$73)+SUMPRODUCT((Grupos!$B$2:$B$73=$A5)*(Grupos!$D$2:$D$73=$B5)*Grupos!$E$2:$E$73) | S5: =Q5-R5 | T5: =N5*3+O5 | U5: =T5*1000000+S5*1000+Q5*10-3 | V5: =1+COUNTIF($U$2:$U$5,">"&U5) | W5: 4 | X5: =INDEX($B$2:$B$5,MATCH(W5,$L$2:$L$5,0)) | Y5: =INDEX($B$2:$B$5,MATCH(W5,$V$2:$V$5,0)) | Z5: =IF(AND(X5<>"",X5=Y5),1,0) | AA5: =INDEX($J$2:$J$5,MATCH(W5,$L$2:$L$5,0)) | AB5: =INDEX($I$2:$I$5,MATCH(W5,$L$2:$L$5,0)) | AC5: =INDEX($G$2:$G$5,MATCH(W5,$L$2:$L$5,0)) | AD5: =INDEX($T$2:$T$5,MATCH(W5,$V$2:$V$5,0)) | AE5: =INDEX($S$2:$S$5,MATCH(W5,$V$2:$V$5,0)) | AF5: =INDEX($Q$2:$Q$5,MATCH(W5,$V$2:$V$5,0))
A6: B | B6: Canadá | C6: =SUMPRODUCT((Grupos!$B$2:$B$73=$A6)*((Grupos!$C$2:$C$73=$B6)+(Grupos!$D$2:$D$73=$B6))*(Grupos!$G$2:$G$73<>"")) | D6: =SUMPRODUCT((Grupos!$B$2:$B$73=$A6)*(Grupos!$C$2:$C$73=$B6)*(Grupos!$G$2:$G$73>Grupos!$H$2:$H$73))+SUMPRODUCT((Grupos!$B$2:$B$73=$A6)*(Grupos!$D$2:$D$73=$B6)*(Grupos!$H$2:$H$73>Grupos!$G$2:$G$73)) | E6: =SUMPRODUCT((Grupos!$B$2:$B$73=$A6)*((Grupos!$C$2:$C$73=$B6)+(Grupos!$D$2:$D$73=$B6))*(Grupos!$G$2:$G$73=Grupos!$H$2:$H$73)*(Grupos!$G$2:$G$73<>"")) | F6: =C6-D6-E6 | G6: =SUMPRODUCT((Grupos!$B$2:$B$73=$A6)*(Grupos!$C$2:$C$73=$B6)*Grupos!$G$2:$G$73)+SUMPRODUCT((Grupos!$B$2:$B$73=$A6)*(Grupos!$D$2:$D$73=$B6)*Grupos!$H$2:$H$73) | H6: =SUMPRODUCT((Grupos!$B$2:$B$73=$A6)*(Grupos!$C$2:$C$73=$B6)*Grupos!$H$2:$H$73)+SUMPRODUCT((Grupos!$B$2:$B$73=$A6)*(Grupos!$D$2:$D$73=$B6)*Grupos!$G$2:$G$73) | I6: =G6-H6 | J6: =D6*3+E6 | K6: =J6*1000000+I6*1000+G6*10-0 | L6: =1+COUNTIF($K$6:$K$9,">"&K6) | M6: =SUMPRODUCT((Grupos!$B$2:$B$73=$A6)*((Grupos!$C$2:$C$73=$B6)+(Grupos!$D$2:$D$73=$B6))*(Grupos!$E$2:$E$73<>"")) | N6: =SUMPRODUCT((Grupos!$B$2:$B$73=$A6)*(Grupos!$C$2:$C$73=$B6)*(Grupos!$E$2:$E$73>Grupos!$F$2:$F$73))+SUMPRODUCT((Grupos!$B$2:$B$73=$A6)*(Grupos!$D$2:$D$73=$B6)*(Grupos!$F$2:$F$73>Grupos!$E$2:$E$73)) | O6: =SUMPRODUCT((Grupos!$B$2:$B$73=$A6)*((Grupos!$C$2:$C$73=$B6)+(Grupos!$D$2:$D$73=$B6))*(Grupos!$E$2:$E$73=Grupos!$F$2:$F$73)*(Grupos!$E$2:$E$73<>"")) | P6: =M6-N6-O6 | Q6: =SUMPRODUCT((Grupos!$B$2:$B$73=$A6)*(Grupos!$C$2:$C$73=$B6)*Grupos!$E$2:$E$73)+SUMPRODUCT((Grupos!$B$2:$B$73=$A6)*(Grupos!$D$2:$D$73=$B6)*Grupos!$F$2:$F$73) | R6: =SUMPRODUCT((Grupos!$B$2:$B$73=$A6)*(Grupos!$C$2:$C$73=$B6)*Grupos!$F$2:$F$73)+SUMPRODUCT((Grupos!$B$2:$B$73=$A6)*(Grupos!$D$2:$D$73=$B6)*Grupos!$E$2:$E$73) | S6: =Q6-R6 | T6: =N6*3+O6 | U6: =T6*1000000+S6*1000+Q6*10-0 | V6: =1+COUNTIF($U$6:$U$9,">"&U6) | W6: 1 | X6: =INDEX($B$6:$B$9,MATCH(W6,$L$6:$L$9,0)) | Y6: =INDEX($B$6:$B$9,MATCH(W6,$V$6:$V$9,0)) | Z6: =IF(AND(X6<>"",X6=Y6),1,0) | AA6: =INDEX($J$6:$J$9,MATCH(W6,$L$6:$L$9,0)) | AB6: =INDEX($I$6:$I$9,MATCH(W6,$L$6:$L$9,0)) | AC6: =INDEX($G$6:$G$9,MATCH(W6,$L$6:$L$9,0)) | AD6: =INDEX($T$6:$T$9,MATCH(W6,$V$6:$V$9,0)) | AE6: =INDEX($S$6:$S$9,MATCH(W6,$V$6:$V$9,0)) | AF6: =INDEX($Q$6:$Q$9,MATCH(W6,$V$6:$V$9,0))
A7: B | B7: Bosnia y Herzegovina | C7: =SUMPRODUCT((Grupos!$B$2:$B$73=$A7)*((Grupos!$C$2:$C$73=$B7)+(Grupos!$D$2:$D$73=$B7))*(Grupos!$G$2:$G$73<>"")) | D7: =SUMPRODUCT((Grupos!$B$2:$B$73=$A7)*(Grupos!$C$2:$C$73=$B7)*(Grupos!$G$2:$G$73>Grupos!$H$2:$H$73))+SUMPRODUCT((Grupos!$B$2:$B$73=$A7)*(Grupos!$D$2:$D$73=$B7)*(Grupos!$H$2:$H$73>Grupos!$G$2:$G$73)) | E7: =SUMPRODUCT((Grupos!$B$2:$B$73=$A7)*((Grupos!$C$2:$C$73=$B7)+(Grupos!$D$2:$D$73=$B7))*(Grupos!$G$2:$G$73=Grupos!$H$2:$H$73)*(Grupos!$G$2:$G$73<>"")) | F7: =C7-D7-E7 | G7: =SUMPRODUCT((Grupos!$B$2:$B$73=$A7)*(Grupos!$C$2:$C$73=$B7)*Grupos!$G$2:$G$73)+SUMPRODUCT((Grupos!$B$2:$B$73=$A7)*(Grupos!$D$2:$D$73=$B7)*Grupos!$H$2:$H$73) | H7: =SUMPRODUCT((Grupos!$B$2:$B$73=$A7)*(Grupos!$C$2:$C$73=$B7)*Grupos!$H$2:$H$73)+SUMPRODUCT((Grupos!$B$2:$B$73=$A7)*(Grupos!$D$2:$D$73=$B7)*Grupos!$G$2:$G$73) | I7: =G7-H7 | J7: =D7*3+E7 | K7: =J7*1000000+I7*1000+G7*10-1 | L7: =1+COUNTIF($K$6:$K$9,">"&K7) | M7: =SUMPRODUCT((Grupos!$B$2:$B$73=$A7)*((Grupos!$C$2:$C$73=$B7)+(Grupos!$D$2:$D$73=$B7))*(Grupos!$E$2:$E$73<>"")) | N7: =SUMPRODUCT((Grupos!$B$2:$B$73=$A7)*(Grupos!$C$2:$C$73=$B7)*(Grupos!$E$2:$E$73>Grupos!$F$2:$F$73))+SUMPRODUCT((Grupos!$B$2:$B$73=$A7)*(Grupos!$D$2:$D$73=$B7)*(Grupos!$F$2:$F$73>Grupos!$E$2:$E$73)) | O7: =SUMPRODUCT((Grupos!$B$2:$B$73=$A7)*((Grupos!$C$2:$C$73=$B7)+(Grupos!$D$2:$D$73=$B7))*(Grupos!$E$2:$E$73=Grupos!$F$2:$F$73)*(Grupos!$E$2:$E$73<>"")) | P7: =M7-N7-O7 | Q7: =SUMPRODUCT((Grupos!$B$2:$B$73=$A7)*(Grupos!$C$2:$C$73=$B7)*Grupos!$E$2:$E$73)+SUMPRODUCT((Grupos!$B$2:$B$73=$A7)*(Grupos!$D$2:$D$73=$B7)*Grupos!$F$2:$F$73) | R7: =SUMPRODUCT((Grupos!$B$2:$B$73=$A7)*(Grupos!$C$2:$C$73=$B7)*Grupos!$F$2:$F$73)+SUMPRODUCT((Grupos!$B$2:$B$73=$A7)*(Grupos!$D$2:$D$73=$B7)*Grupos!$E$2:$E$73) | S7: =Q7-R7 | T7: =N7*3+O7 | U7: =T7*1000000+S7*1000+Q7*10-1 | V7: =1+COUNTIF($U$6:$U$9,">"&U7) | W7: 2 | X7: =INDEX($B$6:$B$9,MATCH(W7,$L$6:$L$9,0)) | Y7: =INDEX($B$6:$B$9,MATCH(W7,$V$6:$V$9,0)) | Z7: =IF(AND(X7<>"",X7=Y7),1,0) | AA7: =INDEX($J$6:$J$9,MATCH(W7,$L$6:$L$9,0)) | AB7: =INDEX($I$6:$I$9,MATCH(W7,$L$6:$L$9,0)) | AC7: =INDEX($G$6:$G$9,MATCH(W7,$L$6:$L$9,0)) | AD7: =INDEX($T$6:$T$9,MATCH(W7,$V$6:$V$9,0)) | AE7: =INDEX($S$6:$S$9,MATCH(W7,$V$6:$V$9,0)) | AF7: =INDEX($Q$6:$Q$9,MATCH(W7,$V$6:$V$9,0))
A8: B | B8: Catar | C8: =SUMPRODUCT((Grupos!$B$2:$B$73=$A8)*((Grupos!$C$2:$C$73=$B8)+(Grupos!$D$2:$D$73=$B8))*(Grupos!$G$2:$G$73<>"")) | D8: =SUMPRODUCT((Grupos!$B$2:$B$73=$A8)*(Grupos!$C$2:$C$73=$B8)*(Grupos!$G$2:$G$73>Grupos!$H$2:$H$73))+SUMPRODUCT((Grupos!$B$2:$B$73=$A8)*(Grupos!$D$2:$D$73=$B8)*(Grupos!$H$2:$H$73>Grupos!$G$2:$G$73)) | E8: =SUMPRODUCT((Grupos!$B$2:$B$73=$A8)*((Grupos!$C$2:$C$73=$B8)+(Grupos!$D$2:$D$73=$B8))*(Grupos!$G$2:$G$73=Grupos!$H$2:$H$73)*(Grupos!$G$2:$G$73<>"")) | F8: =C8-D8-E8 | G8: =SUMPRODUCT((Grupos!$B$2:$B$73=$A8)*(Grupos!$C$2:$C$73=$B8)*Grupos!$G$2:$G$73)+SUMPRODUCT((Grupos!$B$2:$B$73=$A8)*(Grupos!$D$2:$D$73=$B8)*Grupos!$H$2:$H$73) | H8: =SUMPRODUCT((Grupos!$B$2:$B$73=$A8)*(Grupos!$C$2:$C$73=$B8)*Grupos!$H$2:$H$73)+SUMPRODUCT((Grupos!$B$2:$B$73=$A8)*(Grupos!$D$2:$D$73=$B8)*Grupos!$G$2:$G$73) | I8: =G8-H8 | J8: =D8*3+E8 | K8: =J8*1000000+I8*1000+G8*10-2 | L8: =1+COUNTIF($K$6:$K$9,">"&K8) | M8: =SUMPRODUCT((Grupos!$B$2:$B$73=$A8)*((Grupos!$C$2:$C$73=$B8)+(Grupos!$D$2:$D$73=$B8))*(Grupos!$E$2:$E$73<>"")) | N8: =SUMPRODUCT((Grupos!$B$2:$B$73=$A8)*(Grupos!$C$2:$C$73=$B8)*(Grupos!$E$2:$E$73>Grupos!$F$2:$F$73))+SUMPRODUCT((Grupos!$B$2:$B$73=$A8)*(Grupos!$D$2:$D$73=$B8)*(Grupos!$F$2:$F$73>Grupos!$E$2:$E$73)) | O8: =SUMPRODUCT((Grupos!$B$2:$B$73=$A8)*((Grupos!$C$2:$C$73=$B8)+(Grupos!$D$2:$D$73=$B8))*(Grupos!$E$2:$E$73=Grupos!$F$2:$F$73)*(Grupos!$E$2:$E$73<>"")) | P8: =M8-N8-O8 | Q8: =SUMPRODUCT((Grupos!$B$2:$B$73=$A8)*(Grupos!$C$2:$C$73=$B8)*Grupos!$E$2:$E$73)+SUMPRODUCT((Grupos!$B$2:$B$73=$A8)*(Grupos!$D$2:$D$73=$B8)*Grupos!$F$2:$F$73) | R8: =SUMPRODUCT((Grupos!$B$2:$B$73=$A8)*(Grupos!$C$2:$C$73=$B8)*Grupos!$F$2:$F$73)+SUMPRODUCT((Grupos!$B$2:$B$73=$A8)*(Grupos!$D$2:$D$73=$B8)*Grupos!$E$2:$E$73) | S8: =Q8-R8 | T8: =N8*3+O8 | U8: =T8*1000000+S8*1000+Q8*10-2 | V8: =1+COUNTIF($U$6:$U$9,">"&U8) | W8: 3 | X8: =INDEX($B$6:$B$9,MATCH(W8,$L$6:$L$9,0)) | Y8: =INDEX($B$6:$B$9,MATCH(W8,$V$6:$V$9,0)) | Z8: =IF(AND(X8<>"",X8=Y8),1,0) | AA8: =INDEX($J$6:$J$9,MATCH(W8,$L$6:$L$9,0)) | AB8: =INDEX($I$6:$I$9,MATCH(W8,$L$6:$L$9,0)) | AC8: =INDEX($G$6:$G$9,MATCH(W8,$L$6:$L$9,0)) | AD8: =INDEX($T$6:$T$9,MATCH(W8,$V$6:$V$9,0)) | AE8: =INDEX($S$6:$S$9,MATCH(W8,$V$6:$V$9,0)) | AF8: =INDEX($Q$6:$Q$9,MATCH(W8,$V$6:$V$9,0))
A9: B | B9: Suiza | C9: =SUMPRODUCT((Grupos!$B$2:$B$73=$A9)*((Grupos!$C$2:$C$73=$B9)+(Grupos!$D$2:$D$73=$B9))*(Grupos!$G$2:$G$73<>"")) | D9: =SUMPRODUCT((Grupos!$B$2:$B$73=$A9)*(Grupos!$C$2:$C$73=$B9)*(Grupos!$G$2:$G$73>Grupos!$H$2:$H$73))+SUMPRODUCT((Grupos!$B$2:$B$73=$A9)*(Grupos!$D$2:$D$73=$B9)*(Grupos!$H$2:$H$73>Grupos!$G$2:$G$73)) | E9: =SUMPRODUCT((Grupos!$B$2:$B$73=$A9)*((Grupos!$C$2:$C$73=$B9)+(Grupos!$D$2:$D$73=$B9))*(Grupos!$G$2:$G$73=Grupos!$H$2:$H$73)*(Grupos!$G$2:$G$73<>"")) | F9: =C9-D9-E9 | G9: =SUMPRODUCT((Grupos!$B$2:$B$73=$A9)*(Grupos!$C$2:$C$73=$B9)*Grupos!$G$2:$G$73)+SUMPRODUCT((Grupos!$B$2:$B$73=$A9)*(Grupos!$D$2:$D$73=$B9)*Grupos!$H$2:$H$73) | H9: =SUMPRODUCT((Grupos!$B$2:$B$73=$A9)*(Grupos!$C$2:$C$73=$B9)*Grupos!$H$2:$H$73)+SUMPRODUCT((Grupos!$B$2:$B$73=$A9)*(Grupos!$D$2:$D$73=$B9)*Grupos!$G$2:$G$73) | I9: =G9-H9 | J9: =D9*3+E9 | K9: =J9*1000000+I9*1000+G9*10-3 | L9: =1+COUNTIF($K$6:$K$9,">"&K9) | M9: =SUMPRODUCT((Grupos!$B$2:$B$73=$A9)*((Grupos!$C$2:$C$73=$B9)+(Grupos!$D$2:$D$73=$B9))*(Grupos!$E$2:$E$73<>"")) | N9: =SUMPRODUCT((Grupos!$B$2:$B$73=$A9)*(Grupos!$C$2:$C$73=$B9)*(Grupos!$E$2:$E$73>Grupos!$F$2:$F$73))+SUMPRODUCT((Grupos!$B$2:$B$73=$A9)*(Grupos!$D$2:$D$73=$B9)*(Grupos!$F$2:$F$73>Grupos!$E$2:$E$73)) | O9: =SUMPRODUCT((Grupos!$B$2:$B$73=$A9)*((Grupos!$C$2:$C$73=$B9)+(Grupos!$D$2:$D$73=$B9))*(Grupos!$E$2:$E$73=Grupos!$F$2:$F$73)*(Grupos!$E$2:$E$73<>"")) | P9: =M9-N9-O9 | Q9: =SUMPRODUCT((Grupos!$B$2:$B$73=$A9)*(Grupos!$C$2:$C$73=$B9)*Grupos!$E$2:$E$73)+SUMPRODUCT((Grupos!$B$2:$B$73=$A9)*(Grupos!$D$2:$D$73=$B9)*Grupos!$F$2:$F$73) | R9: =SUMPRODUCT((Grupos!$B$2:$B$73=$A9)*(Grupos!$C$2:$C$73=$B9)*Grupos!$F$2:$F$73)+SUMPRODUCT((Grupos!$B$2:$B$73=$A9)*(Grupos!$D$2:$D$73=$B9)*Grupos!$E$2:$E$73) | S9: =Q9-R9 | T9: =N9*3+O9 | U9: =T9*1000000+S9*1000+Q9*10-3 | V9: =1+COUNTIF($U$6:$U$9,">"&U9) | W9: 4 | X9: =INDEX($B$6:$B$9,MATCH(W9,$L$6:$L$9,0)) | Y9: =INDEX($B$6:$B$9,MATCH(W9,$V$6:$V$9,0)) | Z9: =IF(AND(X9<>"",X9=Y9),1,0) | AA9: =INDEX($J$6:$J$9,MATCH(W9,$L$6:$L$9,0)) | AB9: =INDEX($I$6:$I$9,MATCH(W9,$L$6:$L$9,0)) | AC9: =INDEX($G$6:$G$9,MATCH(W9,$L$6:$L$9,0)) | AD9: =INDEX($T$6:$T$9,MATCH(W9,$V$6:$V$9,0)) | AE9: =INDEX($S$6:$S$9,MATCH(W9,$V$6:$V$9,0)) | AF9: =INDEX($Q$6:$Q$9,MATCH(W9,$V$6:$V$9,0))
A10: C | B10: Brasil | C10: =SUMPRODUCT((Grupos!$B$2:$B$73=$A10)*((Grupos!$C$2:$C$73=$B10)+(Grupos!$D$2:$D$73=$B10))*(Grupos!$G$2:$G$73<>"")) | D10: =SUMPRODUCT((Grupos!$B$2:$B$73=$A10)*(Grupos!$C$2:$C$73=$B10)*(Grupos!$G$2:$G$73>Grupos!$H$2:$H$73))+SUMPRODUCT((Grupos!$B$2:$B$73=$A10)*(Grupos!$D$2:$D$73=$B10)*(Grupos!$H$2:$H$73>Grupos!$G$2:$G$73)) | E10: =SUMPRODUCT((Grupos!$B$2:$B$73=$A10)*((Grupos!$C$2:$C$73=$B10)+(Grupos!$D$2:$D$73=$B10))*(Grupos!$G$2:$G$73=Grupos!$H$2:$H$73)*(Grupos!$G$2:$G$73<>"")) | F10: =C10-D10-E10 | G10: =SUMPRODUCT((Grupos!$B$2:$B$73=$A10)*(Grupos!$C$2:$C$73=$B10)*Grupos!$G$2:$G$73)+SUMPRODUCT((Grupos!$B$2:$B$73=$A10)*(Grupos!$D$2:$D$73=$B10)*Grupos!$H$2:$H$73) | H10: =SUMPRODUCT((Grupos!$B$2:$B$73=$A10)*(Grupos!$C$2:$C$73=$B10)*Grupos!$H$2:$H$73)+SUMPRODUCT((Grupos!$B$2:$B$73=$A10)*(Grupos!$D$2:$D$73=$B10)*Grupos!$G$2:$G$73) | I10: =G10-H10 | J10: =D10*3+E10 | K10: =J10*1000000+I10*1000+G10*10-0 | L10: =1+COUNTIF($K$10:$K$13,">"&K10) | M10: =SUMPRODUCT((Grupos!$B$2:$B$73=$A10)*((Grupos!$C$2:$C$73=$B10)+(Grupos!$D$2:$D$73=$B10))*(Grupos!$E$2:$E$73<>"")) | N10: =SUMPRODUCT((Grupos!$B$2:$B$73=$A10)*(Grupos!$C$2:$C$73=$B10)*(Grupos!$E$2:$E$73>Grupos!$F$2:$F$73))+SUMPRODUCT((Grupos!$B$2:$B$73=$A10)*(Grupos!$D$2:$D$73=$B10)*(Grupos!$F$2:$F$73>Grupos!$E$2:$E$73)) | O10: =SUMPRODUCT((Grupos!$B$2:$B$73=$A10)*((Grupos!$C$2:$C$73=$B10)+(Grupos!$D$2:$D$73=$B10))*(Grupos!$E$2:$E$73=Grupos!$F$2:$F$73)*(Grupos!$E$2:$E$73<>"")) | P10: =M10-N10-O10 | Q10: =SUMPRODUCT((Grupos!$B$2:$B$73=$A10)*(Grupos!$C$2:$C$73=$B10)*Grupos!$E$2:$E$73)+SUMPRODUCT((Grupos!$B$2:$B$73=$A10)*(Grupos!$D$2:$D$73=$B10)*Grupos!$F$2:$F$73) | R10: =SUMPRODUCT((Grupos!$B$2:$B$73=$A10)*(Grupos!$C$2:$C$73=$B10)*Grupos!$F$2:$F$73)+SUMPRODUCT((Grupos!$B$2:$B$73=$A10)*(Grupos!$D$2:$D$73=$B10)*Grupos!$E$2:$E$73) | S10: =Q10-R10 | T10: =N10*3+O10 | U10: =T10*1000000+S10*1000+Q10*10-0 | V10: =1+COUNTIF($U$10:$U$13,">"&U10) | W10: 1 | X10: =INDEX($B$10:$B$13,MATCH(W10,$L$10:$L$13,0)) | Y10: =INDEX($B$10:$B$13,MATCH(W10,$V$10:$V$13,0)) | Z10: =IF(AND(X10<>"",X10=Y10),1,0) | AA10: =INDEX($J$10:$J$13,MATCH(W10,$L$10:$L$13,0)) | AB10: =INDEX($I$10:$I$13,MATCH(W10,$L$10:$L$13,0)) | AC10: =INDEX($G$10:$G$13,MATCH(W10,$L$10:$L$13,0)) | AD10: =INDEX($T$10:$T$13,MATCH(W10,$V$10:$V$13,0)) | AE10: =INDEX($S$10:$S$13,MATCH(W10,$V$10:$V$13,0)) | AF10: =INDEX($Q$10:$Q$13,MATCH(W10,$V$10:$V$13,0))
A11: C | B11: Marruecos | C11: =SUMPRODUCT((Grupos!$B$2:$B$73=$A11)*((Grupos!$C$2:$C$73=$B11)+(Grupos!$D$2:$D$73=$B11))*(Grupos!$G$2:$G$73<>"")) | D11: =SUMPRODUCT((Grupos!$B$2:$B$73=$A11)*(Grupos!$C$2:$C$73=$B11)*(Grupos!$G$2:$G$73>Grupos!$H$2:$H$73))+SUMPRODUCT((Grupos!$B$2:$B$73=$A11)*(Grupos!$D$2:$D$73=$B11)*(Grupos!$H$2:$H$73>Grupos!$G$2:$G$73)) | E11: =SUMPRODUCT((Grupos!$B$2:$B$73=$A11)*((Grupos!$C$2:$C$73=$B11)+(Grupos!$D$2:$D$73=$B11))*(Grupos!$G$2:$G$73=Grupos!$H$2:$H$73)*(Grupos!$G$2:$G$73<>"")) | F11: =C11-D11-E11 | G11: =SUMPRODUCT((Grupos!$B$2:$B$73=$A11)*(Grupos!$C$2:$C$73=$B11)*Grupos!$G$2:$G$73)+SUMPRODUCT((Grupos!$B$2:$B$73=$A11)*(Grupos!$D$2:$D$73=$B11)*Grupos!$H$2:$H$73) | H11: =SUMPRODUCT((Grupos!$B$2:$B$73=$A11)*(Grupos!$C$2:$C$73=$B11)*Grupos!$H$2:$H$73)+SUMPRODUCT((Grupos!$B$2:$B$73=$A11)*(Grupos!$D$2:$D$73=$B11)*Grupos!$G$2:$G$73) | I11: =G11-H11 | J11: =D11*3+E11 | K11: =J11*1000000+I11*1000+G11*10-1 | L11: =1+COUNTIF($K$10:$K$13,">"&K11) | M11: =SUMPRODUCT((Grupos!$B$2:$B$73=$A11)*((Grupos!$C$2:$C$73=$B11)+(Grupos!$D$2:$D$73=$B11))*(Grupos!$E$2:$E$73<>"")) | N11: =SUMPRODUCT((Grupos!$B$2:$B$73=$A11)*(Grupos!$C$2:$C$73=$B11)*(Grupos!$E$2:$E$73>Grupos!$F$2:$F$73))+SUMPRODUCT((Grupos!$B$2:$B$73=$A11)*(Grupos!$D$2:$D$73=$B11)*(Grupos!$F$2:$F$73>Grupos!$E$2:$E$73)) | O11: =SUMPRODUCT((Grupos!$B$2:$B$73=$A11)*((Grupos!$C$2:$C$73=$B11)+(Grupos!$D$2:$D$73=$B11))*(Grupos!$E$2:$E$73=Grupos!$F$2:$F$73)*(Grupos!$E$2:$E$73<>"")) | P11: =M11-N11-O11 | Q11: =SUMPRODUCT((Grupos!$B$2:$B$73=$A11)*(Grupos!$C$2:$C$73=$B11)*Grupos!$E$2:$E$73)+SUMPRODUCT((Grupos!$B$2:$B$73=$A11)*(Grupos!$D$2:$D$73=$B11)*Grupos!$F$2:$F$73) | R11: =SUMPRODUCT((Grupos!$B$2:$B$73=$A11)*(Grupos!$C$2:$C$73=$B11)*Grupos!$F$2:$F$73)+SUMPRODUCT((Grupos!$B$2:$B$73=$A11)*(Grupos!$D$2:$D$73=$B11)*Grupos!$E$2:$E$73) | S11: =Q11-R11 | T11: =N11*3+O11 | U11: =T11*1000000+S11*1000+Q11*10-1 | V11: =1+COUNTIF($U$10:$U$13,">"&U11) | W11: 2 | X11: =INDEX($B$10:$B$13,MATCH(W11,$L$10:$L$13,0)) | Y11: =INDEX($B$10:$B$13,MATCH(W11,$V$10:$V$13,0)) | Z11: =IF(AND(X11<>"",X11=Y11),1,0) | AA11: =INDEX($J$10:$J$13,MATCH(W11,$L$10:$L$13,0)) | AB11: =INDEX($I$10:$I$13,MATCH(W11,$L$10:$L$13,0)) | AC11: =INDEX($G$10:$G$13,MATCH(W11,$L$10:$L$13,0)) | AD11: =INDEX($T$10:$T$13,MATCH(W11,$V$10:$V$13,0)) | AE11: =INDEX($S$10:$S$13,MATCH(W11,$V$10:$V$13,0)) | AF11: =INDEX($Q$10:$Q$13,MATCH(W11,$V$10:$V$13,0))
A12: C | B12: Haití | C12: =SUMPRODUCT((Grupos!$B$2:$B$73=$A12)*((Grupos!$C$2:$C$73=$B12)+(Grupos!$D$2:$D$73=$B12))*(Grupos!$G$2:$G$73<>"")) | D12: =SUMPRODUCT((Grupos!$B$2:$B$73=$A12)*(Grupos!$C$2:$C$73=$B12)*(Grupos!$G$2:$G$73>Grupos!$H$2:$H$73))+SUMPRODUCT((Grupos!$B$2:$B$73=$A12)*(Grupos!$D$2:$D$73=$B12)*(Grupos!$H$2:$H$73>Grupos!$G$2:$G$73)) | E12: =SUMPRODUCT((Grupos!$B$2:$B$73=$A12)*((Grupos!$C$2:$C$73=$B12)+(Grupos!$D$2:$D$73=$B12))*(Grupos!$G$2:$G$73=Grupos!$H$2:$H$73)*(Grupos!$G$2:$G$73<>"")) | F12: =C12-D12-E12 | G12: =SUMPRODUCT((Grupos!$B$2:$B$73=$A12)*(Grupos!$C$2:$C$73=$B12)*Grupos!$G$2:$G$73)+SUMPRODUCT((Grupos!$B$2:$B$73=$A12)*(Grupos!$D$2:$D$73=$B12)*Grupos!$H$2:$H$73) | H12: =SUMPRODUCT((Grupos!$B$2:$B$73=$A12)*(Grupos!$C$2:$C$73=$B12)*Grupos!$H$2:$H$73)+SUMPRODUCT((Grupos!$B$2:$B$73=$A12)*(Grupos!$D$2:$D$73=$B12)*Grupos!$G$2:$G$73) | I12: =G12-H12 | J12: =D12*3+E12 | K12: =J12*1000000+I12*1000+G12*10-2 | L12: =1+COUNTIF($K$10:$K$13,">"&K12) | M12: =SUMPRODUCT((Grupos!$B$2:$B$73=$A12)*((Grupos!$C$2:$C$73=$B12)+(Grupos!$D$2:$D$73=$B12))*(Grupos!$E$2:$E$73<>"")) | N12: =SUMPRODUCT((Grupos!$B$2:$B$73=$A12)*(Grupos!$C$2:$C$73=$B12)*(Grupos!$E$2:$E$73>Grupos!$F$2:$F$73))+SUMPRODUCT((Grupos!$B$2:$B$73=$A12)*(Grupos!$D$2:$D$73=$B12)*(Grupos!$F$2:$F$73>Grupos!$E$2:$E$73)) | O12: =SUMPRODUCT((Grupos!$B$2:$B$73=$A12)*((Grupos!$C$2:$C$73=$B12)+(Grupos!$D$2:$D$73=$B12))*(Grupos!$E$2:$E$73=Grupos!$F$2:$F$73)*(Grupos!$E$2:$E$73<>"")) | P12: =M12-N12-O12 | Q12: =SUMPRODUCT((Grupos!$B$2:$B$73=$A12)*(Grupos!$C$2:$C$73=$B12)*Grupos!$E$2:$E$73)+SUMPRODUCT((Grupos!$B$2:$B$73=$A12)*(Grupos!$D$2:$D$73=$B12)*Grupos!$F$2:$F$73) | R12: =SUMPRODUCT((Grupos!$B$2:$B$73=$A12)*(Grupos!$C$2:$C$73=$B12)*Grupos!$F$2:$F$73)+SUMPRODUCT((Grupos!$B$2:$B$73=$A12)*(Grupos!$D$2:$D$73=$B12)*Grupos!$E$2:$E$73) | S12: =Q12-R12 | T12: =N12*3+O12 | U12: =T12*1000000+S12*1000+Q12*10-2 | V12: =1+COUNTIF($U$10:$U$13,">"&U12) | W12: 3 | X12: =INDEX($B$10:$B$13,MATCH(W12,$L$10:$L$13,0)) | Y12: =INDEX($B$10:$B$13,MATCH(W12,$V$10:$V$13,0)) | Z12: =IF(AND(X12<>"",X12=Y12),1,0) | AA12: =INDEX($J$10:$J$13,MATCH(W12,$L$10:$L$13,0)) | AB12: =INDEX($I$10:$I$13,MATCH(W12,$L$10:$L$13,0)) | AC12: =INDEX($G$10:$G$13,MATCH(W12,$L$10:$L$13,0)) | AD12: =INDEX($T$10:$T$13,MATCH(W12,$V$10:$V$13,0)) | AE12: =INDEX($S$10:$S$13,MATCH(W12,$V$10:$V$13,0)) | AF12: =INDEX($Q$10:$Q$13,MATCH(W12,$V$10:$V$13,0))
A13: C | B13: Escocia | C13: =SUMPRODUCT((Grupos!$B$2:$B$73=$A13)*((Grupos!$C$2:$C$73=$B13)+(Grupos!$D$2:$D$73=$B13))*(Grupos!$G$2:$G$73<>"")) | D13: =SUMPRODUCT((Grupos!$B$2:$B$73=$A13)*(Grupos!$C$2:$C$73=$B13)*(Grupos!$G$2:$G$73>Grupos!$H$2:$H$73))+SUMPRODUCT((Grupos!$B$2:$B$73=$A13)*(Grupos!$D$2:$D$73=$B13)*(Grupos!$H$2:$H$73>Grupos!$G$2:$G$73)) | E13: =SUMPRODUCT((Grupos!$B$2:$B$73=$A13)*((Grupos!$C$2:$C$73=$B13)+(Grupos!$D$2:$D$73=$B13))*(Grupos!$G$2:$G$73=Grupos!$H$2:$H$73)*(Grupos!$G$2:$G$73<>"")) | F13: =C13-D13-E13 | G13: =SUMPRODUCT((Grupos!$B$2:$B$73=$A13)*(Grupos!$C$2:$C$73=$B13)*Grupos!$G$2:$G$73)+SUMPRODUCT((Grupos!$B$2:$B$73=$A13)*(Grupos!$D$2:$D$73=$B13)*Grupos!$H$2:$H$73) | H13: =SUMPRODUCT((Grupos!$B$2:$B$73=$A13)*(Grupos!$C$2:$C$73=$B13)*Grupos!$H$2:$H$73)+SUMPRODUCT((Grupos!$B$2:$B$73=$A13)*(Grupos!$D$2:$D$73=$B13)*Grupos!$G$2:$G$73) | I13: =G13-H13 | J13: =D13*3+E13 | K13: =J13*1000000+I13*1000+G13*10-3 | L13: =1+COUNTIF($K$10:$K$13,">"&K13) | M13: =SUMPRODUCT((Grupos!$B$2:$B$73=$A13)*((Grupos!$C$2:$C$73=$B13)+(Grupos!$D$2:$D$73=$B13))*(Grupos!$E$2:$E$73<>"")) | N13: =SUMPRODUCT((Grupos!$B$2:$B$73=$A13)*(Grupos!$C$2:$C$73=$B13)*(Grupos!$E$2:$E$73>Grupos!$F$2:$F$73))+SUMPRODUCT((Grupos!$B$2:$B$73=$A13)*(Grupos!$D$2:$D$73=$B13)*(Grupos!$F$2:$F$73>Grupos!$E$2:$E$73)) | O13: =SUMPRODUCT((Grupos!$B$2:$B$73=$A13)*((Grupos!$C$2:$C$73=$B13)+(Grupos!$D$2:$D$73=$B13))*(Grupos!$E$2:$E$73=Grupos!$F$2:$F$73)*(Grupos!$E$2:$E$73<>"")) | P13: =M13-N13-O13 | Q13: =SUMPRODUCT((Grupos!$B$2:$B$73=$A13)*(Grupos!$C$2:$C$73=$B13)*Grupos!$E$2:$E$73)+SUMPRODUCT((Grupos!$B$2:$B$73=$A13)*(Grupos!$D$2:$D$73=$B13)*Grupos!$F$2:$F$73) | R13: =SUMPRODUCT((Grupos!$B$2:$B$73=$A13)*(Grupos!$C$2:$C$73=$B13)*Grupos!$F$2:$F$73)+SUMPRODUCT((Grupos!$B$2:$B$73=$A13)*(Grupos!$D$2:$D$73=$B13)*Grupos!$E$2:$E$73) | S13: =Q13-R13 | T13: =N13*3+O13 | U13: =T13*1000000+S13*1000+Q13*10-3 | V13: =1+COUNTIF($U$10:$U$13,">"&U13) | W13: 4 | X13: =INDEX($B$10:$B$13,MATCH(W13,$L$10:$L$13,0)) | Y13: =INDEX($B$10:$B$13,MATCH(W13,$V$10:$V$13,0)) | Z13: =IF(AND(X13<>"",X13=Y13),1,0) | AA13: =INDEX($J$10:$J$13,MATCH(W13,$L$10:$L$13,0)) | AB13: =INDEX($I$10:$I$13,MATCH(W13,$L$10:$L$13,0)) | AC13: =INDEX($G$10:$G$13,MATCH(W13,$L$10:$L$13,0)) | AD13: =INDEX($T$10:$T$13,MATCH(W13,$V$10:$V$13,0)) | AE13: =INDEX($S$10:$S$13,MATCH(W13,$V$10:$V$13,0)) | AF13: =INDEX($Q$10:$Q$13,MATCH(W13,$V$10:$V$13,0))
A14: D | B14: Estados Unidos | C14: =SUMPRODUCT((Grupos!$B$2:$B$73=$A14)*((Grupos!$C$2:$C$73=$B14)+(Grupos!$D$2:$D$73=$B14))*(Grupos!$G$2:$G$73<>"")) | D14: =SUMPRODUCT((Grupos!$B$2:$B$73=$A14)*(Grupos!$C$2:$C$73=$B14)*(Grupos!$G$2:$G$73>Grupos!$H$2:$H$73))+SUMPRODUCT((Grupos!$B$2:$B$73=$A14)*(Grupos!$D$2:$D$73=$B14)*(Grupos!$H$2:$H$73>Grupos!$G$2:$G$73)) | E14: =SUMPRODUCT((Grupos!$B$2:$B$73=$A14)*((Grupos!$C$2:$C$73=$B14)+(Grupos!$D$2:$D$73=$B14))*(Grupos!$G$2:$G$73=Grupos!$H$2:$H$73)*(Grupos!$G$2:$G$73<>"")) | F14: =C14-D14-E14 | G14: =SUMPRODUCT((Grupos!$B$2:$B$73=$A14)*(Grupos!$C$2:$C$73=$B14)*Grupos!$G$2:$G$73)+SUMPRODUCT((Grupos!$B$2:$B$73=$A14)*(Grupos!$D$2:$D$73=$B14)*Grupos!$H$2:$H$73) | H14: =SUMPRODUCT((Grupos!$B$2:$B$73=$A14)*(Grupos!$C$2:$C$73=$B14)*Grupos!$H$2:$H$73)+SUMPRODUCT((Grupos!$B$2:$B$73=$A14)*(Grupos!$D$2:$D$73=$B14)*Grupos!$G$2:$G$73) | I14: =G14-H14 | J14: =D14*3+E14 | K14: =J14*1000000+I14*1000+G14*10-0 | L14: =1+COUNTIF($K$14:$K$17,">"&K14) | M14: =SUMPRODUCT((Grupos!$B$2:$B$73=$A14)*((Grupos!$C$2:$C$73=$B14)+(Grupos!$D$2:$D$73=$B14))*(Grupos!$E$2:$E$73<>"")) | N14: =SUMPRODUCT((Grupos!$B$2:$B$73=$A14)*(Grupos!$C$2:$C$73=$B14)*(Grupos!$E$2:$E$73>Grupos!$F$2:$F$73))+SUMPRODUCT((Grupos!$B$2:$B$73=$A14)*(Grupos!$D$2:$D$73=$B14)*(Grupos!$F$2:$F$73>Grupos!$E$2:$E$73)) | O14: =SUMPRODUCT((Grupos!$B$2:$B$73=$A14)*((Grupos!$C$2:$C$73=$B14)+(Grupos!$D$2:$D$73=$B14))*(Grupos!$E$2:$E$73=Grupos!$F$2:$F$73)*(Grupos!$E$2:$E$73<>"")) | P14: =M14-N14-O14 | Q14: =SUMPRODUCT((Grupos!$B$2:$B$73=$A14)*(Grupos!$C$2:$C$73=$B14)*Grupos!$E$2:$E$73)+SUMPRODUCT((Grupos!$B$2:$B$73=$A14)*(Grupos!$D$2:$D$73=$B14)*Grupos!$F$2:$F$73) | R14: =SUMPRODUCT((Grupos!$B$2:$B$73=$A14)*(Grupos!$C$2:$C$73=$B14)*Grupos!$F$2:$F$73)+SUMPRODUCT((Grupos!$B$2:$B$73=$A14)*(Grupos!$D$2:$D$73=$B14)*Grupos!$E$2:$E$73) | S14: =Q14-R14 | T14: =N14*3+O14 | U14: =T14*1000000+S14*1000+Q14*10-0 | V14: =1+COUNTIF($U$14:$U$17,">"&U14) | W14: 1 | X14: =INDEX($B$14:$B$17,MATCH(W14,$L$14:$L$17,0)) | Y14: =INDEX($B$14:$B$17,MATCH(W14,$V$14:$V$17,0)) | Z14: =IF(AND(X14<>"",X14=Y14),1,0) | AA14: =INDEX($J$14:$J$17,MATCH(W14,$L$14:$L$17,0)) | AB14: =INDEX($I$14:$I$17,MATCH(W14,$L$14:$L$17,0)) | AC14: =INDEX($G$14:$G$17,MATCH(W14,$L$14:$L$17,0)) | AD14: =INDEX($T$14:$T$17,MATCH(W14,$V$14:$V$17,0)) | AE14: =INDEX($S$14:$S$17,MATCH(W14,$V$14:$V$17,0)) | AF14: =INDEX($Q$14:$Q$17,MATCH(W14,$V$14:$V$17,0))
A15: D | B15: Paraguay | C15: =SUMPRODUCT((Grupos!$B$2:$B$73=$A15)*((Grupos!$C$2:$C$73=$B15)+(Grupos!$D$2:$D$73=$B15))*(Grupos!$G$2:$G$73<>"")) | D15: =SUMPRODUCT((Grupos!$B$2:$B$73=$A15)*(Grupos!$C$2:$C$73=$B15)*(Grupos!$G$2:$G$73>Grupos!$H$2:$H$73))+SUMPRODUCT((Grupos!$B$2:$B$73=$A15)*(Grupos!$D$2:$D$73=$B15)*(Grupos!$H$2:$H$73>Grupos!$G$2:$G$73)) | E15: =SUMPRODUCT((Grupos!$B$2:$B$73=$A15)*((Grupos!$C$2:$C$73=$B15)+(Grupos!$D$2:$D$73=$B15))*(Grupos!$G$2:$G$73=Grupos!$H$2:$H$73)*(Grupos!$G$2:$G$73<>"")) | F15: =C15-D15-E15 | G15: =SUMPRODUCT((Grupos!$B$2:$B$73=$A15)*(Grupos!$C$2:$C$73=$B15)*Grupos!$G$2:$G$73)+SUMPRODUCT((Grupos!$B$2:$B$73=$A15)*(Grupos!$D$2:$D$73=$B15)*Grupos!$H$2:$H$73) | H15: =SUMPRODUCT((Grupos!$B$2:$B$73=$A15)*(Grupos!$C$2:$C$73=$B15)*Grupos!$H$2:$H$73)+SUMPRODUCT((Grupos!$B$2:$B$73=$A15)*(Grupos!$D$2:$D$73=$B15)*Grupos!$G$2:$G$73) | I15: =G15-H15 | J15: =D15*3+E15 | K15: =J15*1000000+I15*1000+G15*10-1 | L15: =1+COUNTIF($K$14:$K$17,">"&K15) | M15: =SUMPRODUCT((Grupos!$B$2:$B$73=$A15)*((Grupos!$C$2:$C$73=$B15)+(Grupos!$D$2:$D$73=$B15))*(Grupos!$E$2:$E$73<>"")) | N15: =SUMPRODUCT((Grupos!$B$2:$B$73=$A15)*(Grupos!$C$2:$C$73=$B15)*(Grupos!$E$2:$E$73>Grupos!$F$2:$F$73))+SUMPRODUCT((Grupos!$B$2:$B$73=$A15)*(Grupos!$D$2:$D$73=$B15)*(Grupos!$F$2:$F$73>Grupos!$E$2:$E$73)) | O15: =SUMPRODUCT((Grupos!$B$2:$B$73=$A15)*((Grupos!$C$2:$C$73=$B15)+(Grupos!$D$2:$D$73=$B15))*(Grupos!$E$2:$E$73=Grupos!$F$2:$F$73)*(Grupos!$E$2:$E$73<>"")) | P15: =M15-N15-O15 | Q15: =SUMPRODUCT((Grupos!$B$2:$B$73=$A15)*(Grupos!$C$2:$C$73=$B15)*Grupos!$E$2:$E$73)+SUMPRODUCT((Grupos!$B$2:$B$73=$A15)*(Grupos!$D$2:$D$73=$B15)*Grupos!$F$2:$F$73) | R15: =SUMPRODUCT((Grupos!$B$2:$B$73=$A15)*(Grupos!$C$2:$C$73=$B15)*Grupos!$F$2:$F$73)+SUMPRODUCT((Grupos!$B$2:$B$73=$A15)*(Grupos!$D$2:$D$73=$B15)*Grupos!$E$2:$E$73) | S15: =Q15-R15 | T15: =N15*3+O15 | U15: =T15*1000000+S15*1000+Q15*10-1 | V15: =1+COUNTIF($U$14:$U$17,">"&U15) | W15: 2 | X15: =INDEX($B$14:$B$17,MATCH(W15,$L$14:$L$17,0)) | Y15: =INDEX($B$14:$B$17,MATCH(W15,$V$14:$V$17,0)) | Z15: =IF(AND(X15<>"",X15=Y15),1,0) | AA15: =INDEX($J$14:$J$17,MATCH(W15,$L$14:$L$17,0)) | AB15: =INDEX($I$14:$I$17,MATCH(W15,$L$14:$L$17,0)) | AC15: =INDEX($G$14:$G$17,MATCH(W15,$L$14:$L$17,0)) | AD15: =INDEX($T$14:$T$17,MATCH(W15,$V$14:$V$17,0)) | AE15: =INDEX($S$14:$S$17,MATCH(W15,$V$14:$V$17,0)) | AF15: =INDEX($Q$14:$Q$17,MATCH(W15,$V$14:$V$17,0))
A16: D | B16: Australia | C16: =SUMPRODUCT((Grupos!$B$2:$B$73=$A16)*((Grupos!$C$2:$C$73=$B16)+(Grupos!$D$2:$D$73=$B16))*(Grupos!$G$2:$G$73<>"")) | D16: =SUMPRODUCT((Grupos!$B$2:$B$73=$A16)*(Grupos!$C$2:$C$73=$B16)*(Grupos!$G$2:$G$73>Grupos!$H$2:$H$73))+SUMPRODUCT((Grupos!$B$2:$B$73=$A16)*(Grupos!$D$2:$D$73=$B16)*(Grupos!$H$2:$H$73>Grupos!$G$2:$G$73)) | E16: =SUMPRODUCT((Grupos!$B$2:$B$73=$A16)*((Grupos!$C$2:$C$73=$B16)+(Grupos!$D$2:$D$73=$B16))*(Grupos!$G$2:$G$73=Grupos!$H$2:$H$73)*(Grupos!$G$2:$G$73<>"")) | F16: =C16-D16-E16 | G16: =SUMPRODUCT((Grupos!$B$2:$B$73=$A16)*(Grupos!$C$2:$C$73=$B16)*Grupos!$G$2:$G$73)+SUMPRODUCT((Grupos!$B$2:$B$73=$A16)*(Grupos!$D$2:$D$73=$B16)*Grupos!$H$2:$H$73) | H16: =SUMPRODUCT((Grupos!$B$2:$B$73=$A16)*(Grupos!$C$2:$C$73=$B16)*Grupos!$H$2:$H$73)+SUMPRODUCT((Grupos!$B$2:$B$73=$A16)*(Grupos!$D$2:$D$73=$B16)*Grupos!$G$2:$G$73) | I16: =G16-H16 | J16: =D16*3+E16 | K16: =J16*1000000+I16*1000+G16*10-2 | L16: =1+COUNTIF($K$14:$K$17,">"&K16) | M16: =SUMPRODUCT((Grupos!$B$2:$B$73=$A16)*((Grupos!$C$2:$C$73=$B16)+(Grupos!$D$2:$D$73=$B16))*(Grupos!$E$2:$E$73<>"")) | N16: =SUMPRODUCT((Grupos!$B$2:$B$73=$A16)*(Grupos!$C$2:$C$73=$B16)*(Grupos!$E$2:$E$73>Grupos!$F$2:$F$73))+SUMPRODUCT((Grupos!$B$2:$B$73=$A16)*(Grupos!$D$2:$D$73=$B16)*(Grupos!$F$2:$F$73>Grupos!$E$2:$E$73)) | O16: =SUMPRODUCT((Grupos!$B$2:$B$73=$A16)*((Grupos!$C$2:$C$73=$B16)+(Grupos!$D$2:$D$73=$B16))*(Grupos!$E$2:$E$73=Grupos!$F$2:$F$73)*(Grupos!$E$2:$E$73<>"")) | P16: =M16-N16-O16 | Q16: =SUMPRODUCT((Grupos!$B$2:$B$73=$A16)*(Grupos!$C$2:$C$73=$B16)*Grupos!$E$2:$E$73)+SUMPRODUCT((Grupos!$B$2:$B$73=$A16)*(Grupos!$D$2:$D$73=$B16)*Grupos!$F$2:$F$73) | R16: =SUMPRODUCT((Grupos!$B$2:$B$73=$A16)*(Grupos!$C$2:$C$73=$B16)*Grupos!$F$2:$F$73)+SUMPRODUCT((Grupos!$B$2:$B$73=$A16)*(Grupos!$D$2:$D$73=$B16)*Grupos!$E$2:$E$73) | S16: =Q16-R16 | T16: =N16*3+O16 | U16: =T16*1000000+S16*1000+Q16*10-2 | V16: =1+COUNTIF($U$14:$U$17,">"&U16) | W16: 3 | X16: =INDEX($B$14:$B$17,MATCH(W16,$L$14:$L$17,0)) | Y16: =INDEX($B$14:$B$17,MATCH(W16,$V$14:$V$17,0)) | Z16: =IF(AND(X16<>"",X16=Y16),1,0) | AA16: =INDEX($J$14:$J$17,MATCH(W16,$L$14:$L$17,0)) | AB16: =INDEX($I$14:$I$17,MATCH(W16,$L$14:$L$17,0)) | AC16: =INDEX($G$14:$G$17,MATCH(W16,$L$14:$L$17,0)) | AD16: =INDEX($T$14:$T$17,MATCH(W16,$V$14:$V$17,0)) | AE16: =INDEX($S$14:$S$17,MATCH(W16,$V$14:$V$17,0)) | AF16: =INDEX($Q$14:$Q$17,MATCH(W16,$V$14:$V$17,0))
A17: D | B17: Turquía | C17: =SUMPRODUCT((Grupos!$B$2:$B$73=$A17)*((Grupos!$C$2:$C$73=$B17)+(Grupos!$D$2:$D$73=$B17))*(Grupos!$G$2:$G$73<>"")) | D17: =SUMPRODUCT((Grupos!$B$2:$B$73=$A17)*(Grupos!$C$2:$C$73=$B17)*(Grupos!$G$2:$G$73>Grupos!$H$2:$H$73))+SUMPRODUCT((Grupos!$B$2:$B$73=$A17)*(Grupos!$D$2:$D$73=$B17)*(Grupos!$H$2:$H$73>Grupos!$G$2:$G$73)) | E17: =SUMPRODUCT((Grupos!$B$2:$B$73=$A17)*((Grupos!$C$2:$C$73=$B17)+(Grupos!$D$2:$D$73=$B17))*(Grupos!$G$2:$G$73=Grupos!$H$2:$H$73)*(Grupos!$G$2:$G$73<>"")) | F17: =C17-D17-E17 | G17: =SUMPRODUCT((Grupos!$B$2:$B$73=$A17)*(Grupos!$C$2:$C$73=$B17)*Grupos!$G$2:$G$73)+SUMPRODUCT((Grupos!$B$2:$B$73=$A17)*(Grupos!$D$2:$D$73=$B17)*Grupos!$H$2:$H$73) | H17: =SUMPRODUCT((Grupos!$B$2:$B$73=$A17)*(Grupos!$C$2:$C$73=$B17)*Grupos!$H$2:$H$73)+SUMPRODUCT((Grupos!$B$2:$B$73=$A17)*(Grupos!$D$2:$D$73=$B17)*Grupos!$G$2:$G$73) | I17: =G17-H17 | J17: =D17*3+E17 | K17: =J17*1000000+I17*1000+G17*10-3 | L17: =1+COUNTIF($K$14:$K$17,">"&K17) | M17: =SUMPRODUCT((Grupos!$B$2:$B$73=$A17)*((Grupos!$C$2:$C$73=$B17)+(Grupos!$D$2:$D$73=$B17))*(Grupos!$E$2:$E$73<>"")) | N17: =SUMPRODUCT((Grupos!$B$2:$B$73=$A17)*(Grupos!$C$2:$C$73=$B17)*(Grupos!$E$2:$E$73>Grupos!$F$2:$F$73))+SUMPRODUCT((Grupos!$B$2:$B$73=$A17)*(Grupos!$D$2:$D$73=$B17)*(Grupos!$F$2:$F$73>Grupos!$E$2:$E$73)) | O17: =SUMPRODUCT((Grupos!$B$2:$B$73=$A17)*((Grupos!$C$2:$C$73=$B17)+(Grupos!$D$2:$D$73=$B17))*(Grupos!$E$2:$E$73=Grupos!$F$2:$F$73)*(Grupos!$E$2:$E$73<>"")) | P17: =M17-N17-O17 | Q17: =SUMPRODUCT((Grupos!$B$2:$B$73=$A17)*(Grupos!$C$2:$C$73=$B17)*Grupos!$E$2:$E$73)+SUMPRODUCT((Grupos!$B$2:$B$73=$A17)*(Grupos!$D$2:$D$73=$B17)*Grupos!$F$2:$F$73) | R17: =SUMPRODUCT((Grupos!$B$2:$B$73=$A17)*(Grupos!$C$2:$C$73=$B17)*Grupos!$F$2:$F$73)+SUMPRODUCT((Grupos!$B$2:$B$73=$A17)*(Grupos!$D$2:$D$73=$B17)*Grupos!$E$2:$E$73) | S17: =Q17-R17 | T17: =N17*3+O17 | U17: =T17*1000000+S17*1000+Q17*10-3 | V17: =1+COUNTIF($U$14:$U$17,">"&U17) | W17: 4 | X17: =INDEX($B$14:$B$17,MATCH(W17,$L$14:$L$17,0)) | Y17: =INDEX($B$14:$B$17,MATCH(W17,$V$14:$V$17,0)) | Z17: =IF(AND(X17<>"",X17=Y17),1,0) | AA17: =INDEX($J$14:$J$17,MATCH(W17,$L$14:$L$17,0)) | AB17: =INDEX($I$14:$I$17,MATCH(W17,$L$14:$L$17,0)) | AC17: =INDEX($G$14:$G$17,MATCH(W17,$L$14:$L$17,0)) | AD17: =INDEX($T$14:$T$17,MATCH(W17,$V$14:$V$17,0)) | AE17: =INDEX($S$14:$S$17,MATCH(W17,$V$14:$V$17,0)) | AF17: =INDEX($Q$14:$Q$17,MATCH(W17,$V$14:$V$17,0))
A18: E | B18: Alemania | C18: =SUMPRODUCT((Grupos!$B$2:$B$73=$A18)*((Grupos!$C$2:$C$73=$B18)+(Grupos!$D$2:$D$73=$B18))*(Grupos!$G$2:$G$73<>"")) | D18: =SUMPRODUCT((Grupos!$B$2:$B$73=$A18)*(Grupos!$C$2:$C$73=$B18)*(Grupos!$G$2:$G$73>Grupos!$H$2:$H$73))+SUMPRODUCT((Grupos!$B$2:$B$73=$A18)*(Grupos!$D$2:$D$73=$B18)*(Grupos!$H$2:$H$73>Grupos!$G$2:$G$73)) | E18: =SUMPRODUCT((Grupos!$B$2:$B$73=$A18)*((Grupos!$C$2:$C$73=$B18)+(Grupos!$D$2:$D$73=$B18))*(Grupos!$G$2:$G$73=Grupos!$H$2:$H$73)*(Grupos!$G$2:$G$73<>"")) | F18: =C18-D18-E18 | G18: =SUMPRODUCT((Grupos!$B$2:$B$73=$A18)*(Grupos!$C$2:$C$73=$B18)*Grupos!$G$2:$G$73)+SUMPRODUCT((Grupos!$B$2:$B$73=$A18)*(Grupos!$D$2:$D$73=$B18)*Grupos!$H$2:$H$73) | H18: =SUMPRODUCT((Grupos!$B$2:$B$73=$A18)*(Grupos!$C$2:$C$73=$B18)*Grupos!$H$2:$H$73)+SUMPRODUCT((Grupos!$B$2:$B$73=$A18)*(Grupos!$D$2:$D$73=$B18)*Grupos!$G$2:$G$73) | I18: =G18-H18 | J18: =D18*3+E18 | K18: =J18*1000000+I18*1000+G18*10-0 | L18: =1+COUNTIF($K$18:$K$21,">"&K18) | M18: =SUMPRODUCT((Grupos!$B$2:$B$73=$A18)*((Grupos!$C$2:$C$73=$B18)+(Grupos!$D$2:$D$73=$B18))*(Grupos!$E$2:$E$73<>"")) | N18: =SUMPRODUCT((Grupos!$B$2:$B$73=$A18)*(Grupos!$C$2:$C$73=$B18)*(Grupos!$E$2:$E$73>Grupos!$F$2:$F$73))+SUMPRODUCT((Grupos!$B$2:$B$73=$A18)*(Grupos!$D$2:$D$73=$B18)*(Grupos!$F$2:$F$73>Grupos!$E$2:$E$73)) | O18: =SUMPRODUCT((Grupos!$B$2:$B$73=$A18)*((Grupos!$C$2:$C$73=$B18)+(Grupos!$D$2:$D$73=$B18))*(Grupos!$E$2:$E$73=Grupos!$F$2:$F$73)*(Grupos!$E$2:$E$73<>"")) | P18: =M18-N18-O18 | Q18: =SUMPRODUCT((Grupos!$B$2:$B$73=$A18)*(Grupos!$C$2:$C$73=$B18)*Grupos!$E$2:$E$73)+SUMPRODUCT((Grupos!$B$2:$B$73=$A18)*(Grupos!$D$2:$D$73=$B18)*Grupos!$F$2:$F$73) | R18: =SUMPRODUCT((Grupos!$B$2:$B$73=$A18)*(Grupos!$C$2:$C$73=$B18)*Grupos!$F$2:$F$73)+SUMPRODUCT((Grupos!$B$2:$B$73=$A18)*(Grupos!$D$2:$D$73=$B18)*Grupos!$E$2:$E$73) | S18: =Q18-R18 | T18: =N18*3+O18 | U18: =T18*1000000+S18*1000+Q18*10-0 | V18: =1+COUNTIF($U$18:$U$21,">"&U18) | W18: 1 | X18: =INDEX($B$18:$B$21,MATCH(W18,$L$18:$L$21,0)) | Y18: =INDEX($B$18:$B$21,MATCH(W18,$V$18:$V$21,0)) | Z18: =IF(AND(X18<>"",X18=Y18),1,0) | AA18: =INDEX($J$18:$J$21,MATCH(W18,$L$18:$L$21,0)) | AB18: =INDEX($I$18:$I$21,MATCH(W18,$L$18:$L$21,0)) | AC18: =INDEX($G$18:$G$21,MATCH(W18,$L$18:$L$21,0)) | AD18: =INDEX($T$18:$T$21,MATCH(W18,$V$18:$V$21,0)) | AE18: =INDEX($S$18:$S$21,MATCH(W18,$V$18:$V$21,0)) | AF18: =INDEX($Q$18:$Q$21,MATCH(W18,$V$18:$V$21,0))
A19: E | B19: Curazao | C19: =SUMPRODUCT((Grupos!$B$2:$B$73=$A19)*((Grupos!$C$2:$C$73=$B19)+(Grupos!$D$2:$D$73=$B19))*(Grupos!$G$2:$G$73<>"")) | D19: =SUMPRODUCT((Grupos!$B$2:$B$73=$A19)*(Grupos!$C$2:$C$73=$B19)*(Grupos!$G$2:$G$73>Grupos!$H$2:$H$73))+SUMPRODUCT((Grupos!$B$2:$B$73=$A19)*(Grupos!$D$2:$D$73=$B19)*(Grupos!$H$2:$H$73>Grupos!$G$2:$G$73)) | E19: =SUMPRODUCT((Grupos!$B$2:$B$73=$A19)*((Grupos!$C$2:$C$73=$B19)+(Grupos!$D$2:$D$73=$B19))*(Grupos!$G$2:$G$73=Grupos!$H$2:$H$73)*(Grupos!$G$2:$G$73<>"")) | F19: =C19-D19-E19 | G19: =SUMPRODUCT((Grupos!$B$2:$B$73=$A19)*(Grupos!$C$2:$C$73=$B19)*Grupos!$G$2:$G$73)+SUMPRODUCT((Grupos!$B$2:$B$73=$A19)*(Grupos!$D$2:$D$73=$B19)*Grupos!$H$2:$H$73) | H19: =SUMPRODUCT((Grupos!$B$2:$B$73=$A19)*(Grupos!$C$2:$C$73=$B19)*Grupos!$H$2:$H$73)+SUMPRODUCT((Grupos!$B$2:$B$73=$A19)*(Grupos!$D$2:$D$73=$B19)*Grupos!$G$2:$G$73) | I19: =G19-H19 | J19: =D19*3+E19 | K19: =J19*1000000+I19*1000+G19*10-1 | L19: =1+COUNTIF($K$18:$K$21,">"&K19) | M19: =SUMPRODUCT((Grupos!$B$2:$B$73=$A19)*((Grupos!$C$2:$C$73=$B19)+(Grupos!$D$2:$D$73=$B19))*(Grupos!$E$2:$E$73<>"")) | N19: =SUMPRODUCT((Grupos!$B$2:$B$73=$A19)*(Grupos!$C$2:$C$73=$B19)*(Grupos!$E$2:$E$73>Grupos!$F$2:$F$73))+SUMPRODUCT((Grupos!$B$2:$B$73=$A19)*(Grupos!$D$2:$D$73=$B19)*(Grupos!$F$2:$F$73>Grupos!$E$2:$E$73)) | O19: =SUMPRODUCT((Grupos!$B$2:$B$73=$A19)*((Grupos!$C$2:$C$73=$B19)+(Grupos!$D$2:$D$73=$B19))*(Grupos!$E$2:$E$73=Grupos!$F$2:$F$73)*(Grupos!$E$2:$E$73<>"")) | P19: =M19-N19-O19 | Q19: =SUMPRODUCT((Grupos!$B$2:$B$73=$A19)*(Grupos!$C$2:$C$73=$B19)*Grupos!$E$2:$E$73)+SUMPRODUCT((Grupos!$B$2:$B$73=$A19)*(Grupos!$D$2:$D$73=$B19)*Grupos!$F$2:$F$73) | R19: =SUMPRODUCT((Grupos!$B$2:$B$73=$A19)*(Grupos!$C$2:$C$73=$B19)*Grupos!$F$2:$F$73)+SUMPRODUCT((Grupos!$B$2:$B$73=$A19)*(Grupos!$D$2:$D$73=$B19)*Grupos!$E$2:$E$73) | S19: =Q19-R19 | T19: =N19*3+O19 | U19: =T19*1000000+S19*1000+Q19*10-1 | V19: =1+COUNTIF($U$18:$U$21,">"&U19) | W19: 2 | X19: =INDEX($B$18:$B$21,MATCH(W19,$L$18:$L$21,0)) | Y19: =INDEX($B$18:$B$21,MATCH(W19,$V$18:$V$21,0)) | Z19: =IF(AND(X19<>"",X19=Y19),1,0) | AA19: =INDEX($J$18:$J$21,MATCH(W19,$L$18:$L$21,0)) | AB19: =INDEX($I$18:$I$21,MATCH(W19,$L$18:$L$21,0)) | AC19: =INDEX($G$18:$G$21,MATCH(W19,$L$18:$L$21,0)) | AD19: =INDEX($T$18:$T$21,MATCH(W19,$V$18:$V$21,0)) | AE19: =INDEX($S$18:$S$21,MATCH(W19,$V$18:$V$21,0)) | AF19: =INDEX($Q$18:$Q$21,MATCH(W19,$V$18:$V$21,0))
A20: E | B20: Costa de Marfil | C20: =SUMPRODUCT((Grupos!$B$2:$B$73=$A20)*((Grupos!$C$2:$C$73=$B20)+(Grupos!$D$2:$D$73=$B20))*(Grupos!$G$2:$G$73<>"")) | D20: =SUMPRODUCT((Grupos!$B$2:$B$73=$A20)*(Grupos!$C$2:$C$73=$B20)*(Grupos!$G$2:$G$73>Grupos!$H$2:$H$73))+SUMPRODUCT((Grupos!$B$2:$B$73=$A20)*(Grupos!$D$2:$D$73=$B20)*(Grupos!$H$2:$H$73>Grupos!$G$2:$G$73)) | E20: =SUMPRODUCT((Grupos!$B$2:$B$73=$A20)*((Grupos!$C$2:$C$73=$B20)+(Grupos!$D$2:$D$73=$B20))*(Grupos!$G$2:$G$73=Grupos!$H$2:$H$73)*(Grupos!$G$2:$G$73<>"")) | F20: =C20-D20-E20 | G20: =SUMPRODUCT((Grupos!$B$2:$B$73=$A20)*(Grupos!$C$2:$C$73=$B20)*Grupos!$G$2:$G$73)+SUMPRODUCT((Grupos!$B$2:$B$73=$A20)*(Grupos!$D$2:$D$73=$B20)*Grupos!$H$2:$H$73) | H20: =SUMPRODUCT((Grupos!$B$2:$B$73=$A20)*(Grupos!$C$2:$C$73=$B20)*Grupos!$H$2:$H$73)+SUMPRODUCT((Grupos!$B$2:$B$73=$A20)*(Grupos!$D$2:$D$73=$B20)*Grupos!$G$2:$G$73) | I20: =G20-H20 | J20: =D20*3+E20 | K20: =J20*1000000+I20*1000+G20*10-2 | L20: =1+COUNTIF($K$18:$K$21,">"&K20) | M20: =SUMPRODUCT((Grupos!$B$2:$B$73=$A20)*((Grupos!$C$2:$C$73=$B20)+(Grupos!$D$2:$D$73=$B20))*(Grupos!$E$2:$E$73<>"")) | N20: =SUMPRODUCT((Grupos!$B$2:$B$73=$A20)*(Grupos!$C$2:$C$73=$B20)*(Grupos!$E$2:$E$73>Grupos!$F$2:$F$73))+SUMPRODUCT((Grupos!$B$2:$B$73=$A20)*(Grupos!$D$2:$D$73=$B20)*(Grupos!$F$2:$F$73>Grupos!$E$2:$E$73)) | O20: =SUMPRODUCT((Grupos!$B$2:$B$73=$A20)*((Grupos!$C$2:$C$73=$B20)+(Grupos!$D$2:$D$73=$B20))*(Grupos!$E$2:$E$73=Grupos!$F$2:$F$73)*(Grupos!$E$2:$E$73<>"")) | P20: =M20-N20-O20 | Q20: =SUMPRODUCT((Grupos!$B$2:$B$73=$A20)*(Grupos!$C$2:$C$73=$B20)*Grupos!$E$2:$E$73)+SUMPRODUCT((Grupos!$B$2:$B$73=$A20)*(Grupos!$D$2:$D$73=$B20)*Grupos!$F$2:$F$73) | R20: =SUMPRODUCT((Grupos!$B$2:$B$73=$A20)*(Grupos!$C$2:$C$73=$B20)*Grupos!$F$2:$F$73)+SUMPRODUCT((Grupos!$B$2:$B$73=$A20)*(Grupos!$D$2:$D$73=$B20)*Grupos!$E$2:$E$73) | S20: =Q20-R20 | T20: =N20*3+O20 | U20: =T20*1000000+S20*1000+Q20*10-2 | V20: =1+COUNTIF($U$18:$U$21,">"&U20) | W20: 3 | X20: =INDEX($B$18:$B$21,MATCH(W20,$L$18:$L$21,0)) | Y20: =INDEX($B$18:$B$21,MATCH(W20,$V$18:$V$21,0)) | Z20: =IF(AND(X20<>"",X20=Y20),1,0) | AA20: =INDEX($J$18:$J$21,MATCH(W20,$L$18:$L$21,0)) | AB20: =INDEX($I$18:$I$21,MATCH(W20,$L$18:$L$21,0)) | AC20: =INDEX($G$18:$G$21,MATCH(W20,$L$18:$L$21,0)) | AD20: =INDEX($T$18:$T$21,MATCH(W20,$V$18:$V$21,0)) | AE20: =INDEX($S$18:$S$21,MATCH(W20,$V$18:$V$21,0)) | AF20: =INDEX($Q$18:$Q$21,MATCH(W20,$V$18:$V$21,0))
A21: E | B21: Ecuador | C21: =SUMPRODUCT((Grupos!$B$2:$B$73=$A21)*((Grupos!$C$2:$C$73=$B21)+(Grupos!$D$2:$D$73=$B21))*(Grupos!$G$2:$G$73<>"")) | D21: =SUMPRODUCT((Grupos!$B$2:$B$73=$A21)*(Grupos!$C$2:$C$73=$B21)*(Grupos!$G$2:$G$73>Grupos!$H$2:$H$73))+SUMPRODUCT((Grupos!$B$2:$B$73=$A21)*(Grupos!$D$2:$D$73=$B21)*(Grupos!$H$2:$H$73>Grupos!$G$2:$G$73)) | E21: =SUMPRODUCT((Grupos!$B$2:$B$73=$A21)*((Grupos!$C$2:$C$73=$B21)+(Grupos!$D$2:$D$73=$B21))*(Grupos!$G$2:$G$73=Grupos!$H$2:$H$73)*(Grupos!$G$2:$G$73<>"")) | F21: =C21-D21-E21 | G21: =SUMPRODUCT((Grupos!$B$2:$B$73=$A21)*(Grupos!$C$2:$C$73=$B21)*Grupos!$G$2:$G$73)+SUMPRODUCT((Grupos!$B$2:$B$73=$A21)*(Grupos!$D$2:$D$73=$B21)*Grupos!$H$2:$H$73) | H21: =SUMPRODUCT((Grupos!$B$2:$B$73=$A21)*(Grupos!$C$2:$C$73=$B21)*Grupos!$H$2:$H$73)+SUMPRODUCT((Grupos!$B$2:$B$73=$A21)*(Grupos!$D$2:$D$73=$B21)*Grupos!$G$2:$G$73) | I21: =G21-H21 | J21: =D21*3+E21 | K21: =J21*1000000+I21*1000+G21*10-3 | L21: =1+COUNTIF($K$18:$K$21,">"&K21) | M21: =SUMPRODUCT((Grupos!$B$2:$B$73=$A21)*((Grupos!$C$2:$C$73=$B21)+(Grupos!$D$2:$D$73=$B21))*(Grupos!$E$2:$E$73<>"")) | N21: =SUMPRODUCT((Grupos!$B$2:$B$73=$A21)*(Grupos!$C$2:$C$73=$B21)*(Grupos!$E$2:$E$73>Grupos!$F$2:$F$73))+SUMPRODUCT((Grupos!$B$2:$B$73=$A21)*(Grupos!$D$2:$D$73=$B21)*(Grupos!$F$2:$F$73>Grupos!$E$2:$E$73)) | O21: =SUMPRODUCT((Grupos!$B$2:$B$73=$A21)*((Grupos!$C$2:$C$73=$B21)+(Grupos!$D$2:$D$73=$B21))*(Grupos!$E$2:$E$73=Grupos!$F$2:$F$73)*(Grupos!$E$2:$E$73<>"")) | P21: =M21-N21-O21 | Q21: =SUMPRODUCT((Grupos!$B$2:$B$73=$A21)*(Grupos!$C$2:$C$73=$B21)*Grupos!$E$2:$E$73)+SUMPRODUCT((Grupos!$B$2:$B$73=$A21)*(Grupos!$D$2:$D$73=$B21)*Grupos!$F$2:$F$73) | R21: =SUMPRODUCT((Grupos!$B$2:$B$73=$A21)*(Grupos!$C$2:$C$73=$B21)*Grupos!$F$2:$F$73)+SUMPRODUCT((Grupos!$B$2:$B$73=$A21)*(Grupos!$D$2:$D$73=$B21)*Grupos!$E$2:$E$73) | S21: =Q21-R21 | T21: =N21*3+O21 | U21: =T21*1000000+S21*1000+Q21*10-3 | V21: =1+COUNTIF($U$18:$U$21,">"&U21) | W21: 4 | X21: =INDEX($B$18:$B$21,MATCH(W21,$L$18:$L$21,0)) | Y21: =INDEX($B$18:$B$21,MATCH(W21,$V$18:$V$21,0)) | Z21: =IF(AND(X21<>"",X21=Y21),1,0) | AA21: =INDEX($J$18:$J$21,MATCH(W21,$L$18:$L$21,0)) | AB21: =INDEX($I$18:$I$21,MATCH(W21,$L$18:$L$21,0)) | AC21: =INDEX($G$18:$G$21,MATCH(W21,$L$18:$L$21,0)) | AD21: =INDEX($T$18:$T$21,MATCH(W21,$V$18:$V$21,0)) | AE21: =INDEX($S$18:$S$21,MATCH(W21,$V$18:$V$21,0)) | AF21: =INDEX($Q$18:$Q$21,MATCH(W21,$V$18:$V$21,0))
A22: F | B22: Países Bajos | C22: =SUMPRODUCT((Grupos!$B$2:$B$73=$A22)*((Grupos!$C$2:$C$73=$B22)+(Grupos!$D$2:$D$73=$B22))*(Grupos!$G$2:$G$73<>"")) | D22: =SUMPRODUCT((Grupos!$B$2:$B$73=$A22)*(Grupos!$C$2:$C$73=$B22)*(Grupos!$G$2:$G$73>Grupos!$H$2:$H$73))+SUMPRODUCT((Grupos!$B$2:$B$73=$A22)*(Grupos!$D$2:$D$73=$B22)*(Grupos!$H$2:$H$73>Grupos!$G$2:$G$73)) | E22: =SUMPRODUCT((Grupos!$B$2:$B$73=$A22)*((Grupos!$C$2:$C$73=$B22)+(Grupos!$D$2:$D$73=$B22))*(Grupos!$G$2:$G$73=Grupos!$H$2:$H$73)*(Grupos!$G$2:$G$73<>"")) | F22: =C22-D22-E22 | G22: =SUMPRODUCT((Grupos!$B$2:$B$73=$A22)*(Grupos!$C$2:$C$73=$B22)*Grupos!$G$2:$G$73)+SUMPRODUCT((Grupos!$B$2:$B$73=$A22)*(Grupos!$D$2:$D$73=$B22)*Grupos!$H$2:$H$73) | H22: =SUMPRODUCT((Grupos!$B$2:$B$73=$A22)*(Grupos!$C$2:$C$73=$B22)*Grupos!$H$2:$H$73)+SUMPRODUCT((Grupos!$B$2:$B$73=$A22)*(Grupos!$D$2:$D$73=$B22)*Grupos!$G$2:$G$73) | I22: =G22-H22 | J22: =D22*3+E22 | K22: =J22*1000000+I22*1000+G22*10-0 | L22: =1+COUNTIF($K$22:$K$25,">"&K22) | M22: =SUMPRODUCT((Grupos!$B$2:$B$73=$A22)*((Grupos!$C$2:$C$73=$B22)+(Grupos!$D$2:$D$73=$B22))*(Grupos!$E$2:$E$73<>"")) | N22: =SUMPRODUCT((Grupos!$B$2:$B$73=$A22)*(Grupos!$C$2:$C$73=$B22)*(Grupos!$E$2:$E$73>Grupos!$F$2:$F$73))+SUMPRODUCT((Grupos!$B$2:$B$73=$A22)*(Grupos!$D$2:$D$73=$B22)*(Grupos!$F$2:$F$73>Grupos!$E$2:$E$73)) | O22: =SUMPRODUCT((Grupos!$B$2:$B$73=$A22)*((Grupos!$C$2:$C$73=$B22)+(Grupos!$D$2:$D$73=$B22))*(Grupos!$E$2:$E$73=Grupos!$F$2:$F$73)*(Grupos!$E$2:$E$73<>"")) | P22: =M22-N22-O22 | Q22: =SUMPRODUCT((Grupos!$B$2:$B$73=$A22)*(Grupos!$C$2:$C$73=$B22)*Grupos!$E$2:$E$73)+SUMPRODUCT((Grupos!$B$2:$B$73=$A22)*(Grupos!$D$2:$D$73=$B22)*Grupos!$F$2:$F$73) | R22: =SUMPRODUCT((Grupos!$B$2:$B$73=$A22)*(Grupos!$C$2:$C$73=$B22)*Grupos!$F$2:$F$73)+SUMPRODUCT((Grupos!$B$2:$B$73=$A22)*(Grupos!$D$2:$D$73=$B22)*Grupos!$E$2:$E$73) | S22: =Q22-R22 | T22: =N22*3+O22 | U22: =T22*1000000+S22*1000+Q22*10-0 | V22: =1+COUNTIF($U$22:$U$25,">"&U22) | W22: 1 | X22: =INDEX($B$22:$B$25,MATCH(W22,$L$22:$L$25,0)) | Y22: =INDEX($B$22:$B$25,MATCH(W22,$V$22:$V$25,0)) | Z22: =IF(AND(X22<>"",X22=Y22),1,0) | AA22: =INDEX($J$22:$J$25,MATCH(W22,$L$22:$L$25,0)) | AB22: =INDEX($I$22:$I$25,MATCH(W22,$L$22:$L$25,0)) | AC22: =INDEX($G$22:$G$25,MATCH(W22,$L$22:$L$25,0)) | AD22: =INDEX($T$22:$T$25,MATCH(W22,$V$22:$V$25,0)) | AE22: =INDEX($S$22:$S$25,MATCH(W22,$V$22:$V$25,0)) | AF22: =INDEX($Q$22:$Q$25,MATCH(W22,$V$22:$V$25,0))
A23: F | B23: Japón | C23: =SUMPRODUCT((Grupos!$B$2:$B$73=$A23)*((Grupos!$C$2:$C$73=$B23)+(Grupos!$D$2:$D$73=$B23))*(Grupos!$G$2:$G$73<>"")) | D23: =SUMPRODUCT((Grupos!$B$2:$B$73=$A23)*(Grupos!$C$2:$C$73=$B23)*(Grupos!$G$2:$G$73>Grupos!$H$2:$H$73))+SUMPRODUCT((Grupos!$B$2:$B$73=$A23)*(Grupos!$D$2:$D$73=$B23)*(Grupos!$H$2:$H$73>Grupos!$G$2:$G$73)) | E23: =SUMPRODUCT((Grupos!$B$2:$B$73=$A23)*((Grupos!$C$2:$C$73=$B23)+(Grupos!$D$2:$D$73=$B23))*(Grupos!$G$2:$G$73=Grupos!$H$2:$H$73)*(Grupos!$G$2:$G$73<>"")) | F23: =C23-D23-E23 | G23: =SUMPRODUCT((Grupos!$B$2:$B$73=$A23)*(Grupos!$C$2:$C$73=$B23)*Grupos!$G$2:$G$73)+SUMPRODUCT((Grupos!$B$2:$B$73=$A23)*(Grupos!$D$2:$D$73=$B23)*Grupos!$H$2:$H$73) | H23: =SUMPRODUCT((Grupos!$B$2:$B$73=$A23)*(Grupos!$C$2:$C$73=$B23)*Grupos!$H$2:$H$73)+SUMPRODUCT((Grupos!$B$2:$B$73=$A23)*(Grupos!$D$2:$D$73=$B23)*Grupos!$G$2:$G$73) | I23: =G23-H23 | J23: =D23*3+E23 | K23: =J23*1000000+I23*1000+G23*10-1 | L23: =1+COUNTIF($K$22:$K$25,">"&K23) | M23: =SUMPRODUCT((Grupos!$B$2:$B$73=$A23)*((Grupos!$C$2:$C$73=$B23)+(Grupos!$D$2:$D$73=$B23))*(Grupos!$E$2:$E$73<>"")) | N23: =SUMPRODUCT((Grupos!$B$2:$B$73=$A23)*(Grupos!$C$2:$C$73=$B23)*(Grupos!$E$2:$E$73>Grupos!$F$2:$F$73))+SUMPRODUCT((Grupos!$B$2:$B$73=$A23)*(Grupos!$D$2:$D$73=$B23)*(Grupos!$F$2:$F$73>Grupos!$E$2:$E$73)) | O23: =SUMPRODUCT((Grupos!$B$2:$B$73=$A23)*((Grupos!$C$2:$C$73=$B23)+(Grupos!$D$2:$D$73=$B23))*(Grupos!$E$2:$E$73=Grupos!$F$2:$F$73)*(Grupos!$E$2:$E$73<>"")) | P23: =M23-N23-O23 | Q23: =SUMPRODUCT((Grupos!$B$2:$B$73=$A23)*(Grupos!$C$2:$C$73=$B23)*Grupos!$E$2:$E$73)+SUMPRODUCT((Grupos!$B$2:$B$73=$A23)*(Grupos!$D$2:$D$73=$B23)*Grupos!$F$2:$F$73) | R23: =SUMPRODUCT((Grupos!$B$2:$B$73=$A23)*(Grupos!$C$2:$C$73=$B23)*Grupos!$F$2:$F$73)+SUMPRODUCT((Grupos!$B$2:$B$73=$A23)*(Grupos!$D$2:$D$73=$B23)*Grupos!$E$2:$E$73) | S23: =Q23-R23 | T23: =N23*3+O23 | U23: =T23*1000000+S23*1000+Q23*10-1 | V23: =1+COUNTIF($U$22:$U$25,">"&U23) | W23: 2 | X23: =INDEX($B$22:$B$25,MATCH(W23,$L$22:$L$25,0)) | Y23: =INDEX($B$22:$B$25,MATCH(W23,$V$22:$V$25,0)) | Z23: =IF(AND(X23<>"",X23=Y23),1,0) | AA23: =INDEX($J$22:$J$25,MATCH(W23,$L$22:$L$25,0)) | AB23: =INDEX($I$22:$I$25,MATCH(W23,$L$22:$L$25,0)) | AC23: =INDEX($G$22:$G$25,MATCH(W23,$L$22:$L$25,0)) | AD23: =INDEX($T$22:$T$25,MATCH(W23,$V$22:$V$25,0)) | AE23: =INDEX($S$22:$S$25,MATCH(W23,$V$22:$V$25,0)) | AF23: =INDEX($Q$22:$Q$25,MATCH(W23,$V$22:$V$25,0))
A24: F | B24: Suecia | C24: =SUMPRODUCT((Grupos!$B$2:$B$73=$A24)*((Grupos!$C$2:$C$73=$B24)+(Grupos!$D$2:$D$73=$B24))*(Grupos!$G$2:$G$73<>"")) | D24: =SUMPRODUCT((Grupos!$B$2:$B$73=$A24)*(Grupos!$C$2:$C$73=$B24)*(Grupos!$G$2:$G$73>Grupos!$H$2:$H$73))+SUMPRODUCT((Grupos!$B$2:$B$73=$A24)*(Grupos!$D$2:$D$73=$B24)*(Grupos!$H$2:$H$73>Grupos!$G$2:$G$73)) | E24: =SUMPRODUCT((Grupos!$B$2:$B$73=$A24)*((Grupos!$C$2:$C$73=$B24)+(Grupos!$D$2:$D$73=$B24))*(Grupos!$G$2:$G$73=Grupos!$H$2:$H$73)*(Grupos!$G$2:$G$73<>"")) | F24: =C24-D24-E24 | G24: =SUMPRODUCT((Grupos!$B$2:$B$73=$A24)*(Grupos!$C$2:$C$73=$B24)*Grupos!$G$2:$G$73)+SUMPRODUCT((Grupos!$B$2:$B$73=$A24)*(Grupos!$D$2:$D$73=$B24)*Grupos!$H$2:$H$73) | H24: =SUMPRODUCT((Grupos!$B$2:$B$73=$A24)*(Grupos!$C$2:$C$73=$B24)*Grupos!$H$2:$H$73)+SUMPRODUCT((Grupos!$B$2:$B$73=$A24)*(Grupos!$D$2:$D$73=$B24)*Grupos!$G$2:$G$73) | I24: =G24-H24 | J24: =D24*3+E24 | K24: =J24*1000000+I24*1000+G24*10-2 | L24: =1+COUNTIF($K$22:$K$25,">"&K24) | M24: =SUMPRODUCT((Grupos!$B$2:$B$73=$A24)*((Grupos!$C$2:$C$73=$B24)+(Grupos!$D$2:$D$73=$B24))*(Grupos!$E$2:$E$73<>"")) | N24: =SUMPRODUCT((Grupos!$B$2:$B$73=$A24)*(Grupos!$C$2:$C$73=$B24)*(Grupos!$E$2:$E$73>Grupos!$F$2:$F$73))+SUMPRODUCT((Grupos!$B$2:$B$73=$A24)*(Grupos!$D$2:$D$73=$B24)*(Grupos!$F$2:$F$73>Grupos!$E$2:$E$73)) | O24: =SUMPRODUCT((Grupos!$B$2:$B$73=$A24)*((Grupos!$C$2:$C$73=$B24)+(Grupos!$D$2:$D$73=$B24))*(Grupos!$E$2:$E$73=Grupos!$F$2:$F$73)*(Grupos!$E$2:$E$73<>"")) | P24: =M24-N24-O24 | Q24: =SUMPRODUCT((Grupos!$B$2:$B$73=$A24)*(Grupos!$C$2:$C$73=$B24)*Grupos!$E$2:$E$73)+SUMPRODUCT((Grupos!$B$2:$B$73=$A24)*(Grupos!$D$2:$D$73=$B24)*Grupos!$F$2:$F$73) | R24: =SUMPRODUCT((Grupos!$B$2:$B$73=$A24)*(Grupos!$C$2:$C$73=$B24)*Grupos!$F$2:$F$73)+SUMPRODUCT((Grupos!$B$2:$B$73=$A24)*(Grupos!$D$2:$D$73=$B24)*Grupos!$E$2:$E$73) | S24: =Q24-R24 | T24: =N24*3+O24 | U24: =T24*1000000+S24*1000+Q24*10-2 | V24: =1+COUNTIF($U$22:$U$25,">"&U24) | W24: 3 | X24: =INDEX($B$22:$B$25,MATCH(W24,$L$22:$L$25,0)) | Y24: =INDEX($B$22:$B$25,MATCH(W24,$V$22:$V$25,0)) | Z24: =IF(AND(X24<>"",X24=Y24),1,0) | AA24: =INDEX($J$22:$J$25,MATCH(W24,$L$22:$L$25,0)) | AB24: =INDEX($I$22:$I$25,MATCH(W24,$L$22:$L$25,0)) | AC24: =INDEX($G$22:$G$25,MATCH(W24,$L$22:$L$25,0)) | AD24: =INDEX($T$22:$T$25,MATCH(W24,$V$22:$V$25,0)) | AE24: =INDEX($S$22:$S$25,MATCH(W24,$V$22:$V$25,0)) | AF24: =INDEX($Q$22:$Q$25,MATCH(W24,$V$22:$V$25,0))
